Workbook

Sheet Cover
B2: PROJECT IRONBEND
B3: Northline Precision Pipe Bending & Fabrication Ltd. — Sell-Side Valuation & Deal Economics Model
B5: Strictly Private & Confidential
B7: CONTENTS
B8: 1. Assumptions | C8: Scenario switch, historical financials, EBITDA normalization, operating & financing assumptions
B9: 2. Income Statement | C9: Historical (2021-2025E) and 5-year projected P&L (2026E-2030E), scenario-driven
B10: 3. Balance Sheet | C10: Post-close opening balance sheet and 5-year projection
B11: 4. Cash Flow & Debt Schedule | C11: Senior debt & seller note amortization, and the resulting cash flow statement
B12: 5. Valuation | C12: Adjusted EBITDA build-through to Enterprise Value and Equity Value at the active multiple
B13: 6. Sources & Uses | C13: Transaction funding structure — senior debt, seller note, equity rollover, sponsor equity
B14: 7. Advisor Fee | C14: Modified Lehman tiered success-fee calculation on transaction value
B15: 8. Sensitivity | C15: EV/EBITDA multiple sensitivity across Enterprise Value and advisor fee
B16: 9. Returns Analysis | C16: Illustrative 5-year sponsor MOIC / IRR at the active case
B18: DEAL SNAPSHOT (per CIM)
B19: 2025E Revenue | D19: $9.4M CAD
B20: 2025E EBITDA Margin (disclosed) | D20: 22.3%
B21: Operating History | D21: 31 years
B22: CIM Indicative EV Range | D22: $9.0M – $13.0M CAD (4.5x – 6.5x Adj. EBITDA)
B25: All figures in CAD $ millions unless otherwise labeled. Projected financial statements (2026E-2030E) are illustrative, built on assumptions not disclosed in the CIM (flagged throughout), for discussion purposes only. Not a substitute for confirmatory diligence or a formal quality-of-earnings report.

Sheet Assumptions
F1: STRICTLY CONFIDENTIAL
B2: KEY ASSUMPTIONS & INPUTS
B4: Transaction Overview
B5: Target Company | C5: Northline Precision Pipe Bending & Fabrication Ltd. ('Project Ironbend')
B6: Industry | C6: ASME 'U'-Stamp & National Board Certified Pipe Bending / Pressure Vessel Fabrication
B7: Location | C7: Edmonton, Alberta, Canada
B8: Reporting Currency / Units | C8: CAD $ in millions, unless otherwise noted
B9: Assumed Transaction Structure | C9: Cash-Free, Debt-Free (CFDF) at close
B10: Assumed Close / Projection Start | C10: 2025E year-end; Post-Close Years 1-5 = 2026E-2030E
B11: Customer Concentration (per CIM, Section XII) | C11: Top 5 customers ~59% of revenue; no single customer exceeds ~18%
B12: SCENARIO CASE SWITCH — Drives Growth, Margin, Multiple & Leverage Throughout the Model
B13: Selected Scenario | C13: Base Case
B15: Scenario Driver | C15: Low Case | D15: Base Case | E15: High Case
B16: Revenue Growth (2026E-2030E, p.a.) | C16: 0.03 | D16: 0.055 | E16: 0.08
B17: EBITDA Margin Expansion (bps / year) | C17: 25 | D17: 50 | E17: 90
B18: EV / EBITDA Multiple (Entry & Exit) | C18: 4.5 | D18: 5.5 | E18: 6.5
B19: Senior Debt Leverage (x Adj. EBITDA) | C19: 2 | D19: 2.5 | E19: 3
B21: Active Case Drivers (auto-selected from Selected Scenario above)
B22: Revenue Growth (Active) | C22: =INDEX(C16:E16,MATCH(C13,$C$15:$E$15,0)) -> 0.055
B23: EBITDA Margin Expansion (Active, bps/yr) | C23: =INDEX(C17:E17,MATCH(C13,$C$15:$E$15,0)) -> 50
B24: EV / EBITDA Multiple (Active) | C24: =INDEX(C18:E18,MATCH(C13,$C$15:$E$15,0)) -> 5.5
B25: Senior Debt Leverage (Active) | C25: =INDEX(C19:E19,MATCH(C13,$C$15:$E$15,0)) -> 2.5
B27: Change 'Selected Scenario' above (dropdown) to Low Case / Base Case / High Case and every downstream tab — Income Statement, Balance Sheet, Cash Flow, Valuation, Sources & Uses, Advisor Fee, and Returns — recalculates automatically.
B29: Historical Financials (per CIM, p.9)
B30: Fiscal Year | C30: Revenue ($M) | D30: YoY Growth | E30: EBITDA Margin (%) | F30: Implied EBITDA ($M)
B31: 2021 | C31: 6.8 | E31: 0.162 | F31: =C31*E31 -> 1.1016
B32: 2022 | C32: 7.6 | D32: =C32/C31-1 -> 0.11764706 | E32: 0.178 | F32: =C32*E32 -> 1.3528
B33: 2023 | C33: 8.3 | D33: =C33/C32-1 -> 0.092105263 | E33: 0.193 | F33: =C33*E33 -> 1.6019
B34: 2024 | C34: 8.9 | D34: =C34/C33-1 -> 0.072289157 | E34: 0.208 | F34: =C34*E34 -> 1.8512
B35: 2025E | C35: 9.4 | D35: =C35/C34-1 -> 0.056179775 | E35: 0.223 | F35: =C35*E35 -> 2.0962
B36: Revenue CAGR (2021 – 2025E) | C36: =(C35/C31)^(1/4)-1 -> 0.084313176
B39: EBITDA Normalization (2025E) — per CIM p.10, management-indicated, preliminary
B40: Line Item | C40: $M CAD
B41: Reported EBITDA (2025E) | C41: 1.65
B42: (+) Owner Compensation Add-Back | C42: 0.28
B43: (+) Non-Recurring Legal / Advisory Costs | C43: 0.09
B44: (+) One-Time Equipment Relocation | C44: 0.06
B45: (–) Normalized Market-Rate Management Cost | C45: -0.08
B46: Adjusted EBITDA (2025E) | C46: =SUM(C41:C45) -> 2
B47: Adjusted EBITDA Margin (% of 2025E Revenue) | C47: =C46/C35 -> 0.21276596
...

Sheet Income Statement
F1: STRICTLY CONFIDENTIAL
B2: INCOME STATEMENT
B3: Historical (per CIM) & Projected (Illustrative, Post-Close Years 1-5)
B5: ($M CAD) | C5: 2021 | D5: 2022 | E5: 2023 | F5: 2024 | G5: 2025E | H5: 2026E | I5: 2027E | J5: 2028E | K5: 2029E | L5: 2030E
B6: Revenue | C6: =Assumptions!C31 -> 6.8 | D6: =Assumptions!C32 -> 7.6 | E6: =Assumptions!C33 -> 8.3 | F6: =Assumptions!C34 -> 8.9 | G6: =Assumptions!C35 -> 9.4 | H6: =G6*(1+Assumptions!C22) -> 9.917 | I6: =H6*(1+Assumptions!C22) -> 10.462435 | J6: =I6*(1+Assumptions!C22) -> 11.037869 | K6: =J6*(1+Assumptions!C22) -> 11.644952 | L6: =K6*(1+Assumptions!C22) -> 12.285424
B7: Revenue Growth % | D7: =D6/C6-1 -> 0.11764706 | E7: =E6/D6-1 -> 0.092105263 | F7: =F6/E6-1 -> 0.072289157 | G7: =G6/F6-1 -> 0.056179775 | H7: =H6/G6-1 -> 0.055 | I7: =I6/H6-1 -> 0.055 | J7: =J6/I6-1 -> 0.055 | K7: =K6/J6-1 -> 0.055 | L7: =L6/K6-1 -> 0.055
B8: Gross Margin % (assumption) | C8: =Assumptions!C63 -> 0.37 | D8: =Assumptions!C63 -> 0.37 | E8: =Assumptions!C63 -> 0.37 | F8: =Assumptions!C63 -> 0.37 | G8: =Assumptions!C63 -> 0.37 | H8: =Assumptions!C63 -> 0.37 | I8: =Assumptions!C63 -> 0.37 | J8: =Assumptions!C63 -> 0.37 | K8: =Assumptions!C63 -> 0.37 | L8: =Assumptions!C63 -> 0.37
B9: Gross Profit | C9: =C6*C8 -> 2.516 | D9: =D6*D8 -> 2.812 | E9: =E6*E8 -> 3.071 | F9: =F6*F8 -> 3.293 | G9: =G6*G8 -> 3.478 | H9: =H6*H8 -> 3.66929 | I9: =I6*I8 -> 3.871101 | J9: =J6*J8 -> 4.0840115 | ... L9: =L6*L8 -> 4.5456069
B10: EBITDA Margin % | C10: =Assumptions!E31 -> 0.162 | D10: =Assumptions!E32 -> 0.178 | E10: =Assumptions!E33 -> 0.193 | F10: =Assumptions!E34 -> 0.208 | G10: =Assumptions!E35 -> 0.223 | H10: =G10+Assumptions!C23/10000 -> 0.228 | I10: =H10+Assumptions!C23/10000 -> 0.233 | J10: =I10+Assumptions!C23/10000 -> 0.238 | K10: =J10+Assumptions!C23/10000 -> 0.243 | L10: =K10+Assumptions!C23/10000 -> 0.248
B11: EBITDA | C11: =C6*C10 -> 1.1016 | D11: =D6*D10 -> 1.3528 | E11: =E6*E10 -> 1.6019 | F11: =F6*F10 -> 1.8512 | G11: =G6*G10 -> 2.0962 | H11: =H6*H10 -> 2.261076 | I11: =I6*I10 -> 2.4377474 | J11: =J6*J10 -> 2.6270128 | ... L11: =L6*L10 -> 3.0467852
B12: Operating Expenses (SG&A, derived) | C12: =C9-C11 -> 1.4144 | D12: =D9-D11 -> 1.4592 | E12: =E9-E11 -> 1.4691 | F12: =F9-F11 -> 1.4418 | G12: =G9-G11 -> 1.3818 | H12: =H9-H11 -> 1.408214 | I12: =I9-I11 -> 1.4333536 | J12: =J9-J11 -> 1.4569987 | ... L12: =L9-L11 -> 1.4988217
B13: Depreciation & Amortization | C13: =C6*Assumptions!C64 -> 0.204 | D13: =D6*Assumptions!C64 -> 0.228 | E13: =E6*Assumptions!C64 -> 0.249 | F13: =F6*Assumptions!C64 -> 0.267 | G13: =G6*Assumptions!C64 -> 0.282 | H13: =H6*Assumptions!C64 -> 0.29751 | I13: =I6*Assumptions!C64 -> 0.31387305 | J13: =J6*Assumptions!C64 -> 0.33113607 | K13: =K6*Assumptions!C64 -> 0.34934855 | L13: =L6*Assumptions!C64 -> 0.36856272
B14: EBIT | C14: =C11-C13 -> 0.8976 | D14: =D11-D13 -> 1.1248 | E14: =E11-E13 -> 1.3529 | F14: =F11-F13 -> 1.5842 | G14: =G11-G13 -> 1.8142 | H14: =H11-H13 -> 1.963566 | I14: =I11-I13 -> 2.1238743 | J14: =J11-J13 -> 2.2958767 | ... L14: =L11-L13 -> 2.6782224
B15: Interest Expense | C15: n/a | D15: n/a | E15: n/a | F15: n/a | G15: n/a | H15: ='Cash Flow & Debt Schedule'!C17 -> 0.5255 | I15: ='Cash Flow & Debt Schedule'!D17 -> 0.45258333 | J15: ='Cash Flow & Debt Schedule'!E17 -> 0.37966667 | K15: ='Cash Flow & Debt Schedule'!F17 -> 0.30675 | L15: ='Cash Flow & Debt Schedule'!G17 -> 0.23383333
B16: Earnings Before Tax (EBT) | C16: n/a | D16: n/a | E16: n/a | F16: n/a | G16: n/a | H16: =H14-H15 -> 1.438066 | I16: =I14-I15 -> 1.671291 | J16: =J14-J15 -> 1.9162101 | K16: =K14-K15 -> 2.1736247 | L16: =L14-L15 -> 2.4443891
B17: Income Taxes | C17: n/a | D17: n/a | E17: n/a | F17: n/a | G17: n/a | H17: =MAX(H16,0)*Assumptions!C71 -> 0.3595165 | I17: =MAX(I16,0)*Assumptions!C71 -> 0.41782274 | J17: =MAX(J16,0)*Assumptions!C71 -> 0.47905252 | K17: =MAX(K16,0)*Assumptions!C71 -> 0.54340618 | L17: =MAX(L16,0)*Assumptions!C71 -> 0.61109728
B18: Net Income | C18: n/a | D18: n/a | E18: n/a | F18: n/a | G18: n/a | H18: =H16-H17 -> 1.0785495 | I18: =I16-I17 -> 1.2534682 | J18: =J16-J17 -> 1.4371576 | K18: =K16-K17 -> 1.6302185 | L18: =L16-L17 -> 1.8332918

Sheet Balance Sheet
F1: STRICTLY CONFIDENTIAL
B2: BALANCE SHEET
B3: Post-Close Opening Balance Sheet & 5-Year Projection (Illustrative)
B5: ($M CAD) | C5: 2025E (Close) | D5: 2026E | E5: 2027E | F5: 2028E | G5: 2029E | H5: 2030E
B6: Assets
B7: Cash | C7: =Assumptions!C70 -> 0.3 | D7: ='Cash Flow & Debt Schedule'!C35 -> 0.57583197 | E7: ='Cash Flow & Debt Schedule'!D35 -> 1.0282665 | F7: ='Cash Flow & Debt Schedule'!E35 -> 1.6661669 | G7: ='Cash Flow & Debt Schedule'!F35 -> 2.4990024 | H7: ='Cash Flow & Debt Schedule'!G35 -> 3.5368886
B8: Accounts Receivable | C8: ='Income Statement'!G6*Assumptions!C66 -> 1.128 | D8: ='Income Statement'!H6*Assumptions!C66 -> 1.19004 | E8: ='Income Statement'!I6*Assumptions!C66 -> 1.2554922 | F8: ='Income Statement'!J6*Assumptions!C66 -> 1.3245443 | G8: ='Income Statement'!K6*Assumptions!C66 -> 1.3973942 | H8: ='Income Statement'!L6*Assumptions!C66 -> 1.4742509
B9: Inventory | C9: =('Income Statement'!G6-'Income Statement'!G9)*Assumptions!C67 -> 0.5922 | D9: =('Income Statement'!H6-'Income Statement'!H9)*Assumptions!C67 -> 0.624771 | E9: =('Income Statement'!I6-'Income Statement'!I9)*Assumptions!C67 -> 0.6591334 | F9: =('Income Statement'!J6-'Income Statement'!J9)*Assumptions!C67 -> 0.69538574 | G9: =('Income Statement'!K6-'Income Statement'!K9)*Assumptions!C67 -> 0.73363196 | H9: =('Income Statement'!L6-'Income Statement'!L9)*Assumptions!C67 -> 0.77398172
B10: Net PP&E | C10: ='Income Statement'!G6*Assumptions!C69 -> 2.82 | D10: =C10-'Cash Flow & Debt Schedule'!C27-'Cash Flow & Debt Schedule'!C21 -> 2.72083 | E10: =D10-'Cash Flow & Debt Schedule'!D27-'Cash Flow & Debt Schedule'!D21 -> 2.6162056 | F10: =E10-'Cash Flow & Debt Schedule'!E27-'Cash Flow & Debt Schedule'!E21 -> 2.505827 | G10: =F10-'Cash Flow & Debt Schedule'!F27-'Cash Flow & Debt Schedule'!F21 -> 2.3893774 | H10: =G10-'Cash Flow & Debt Schedule'!G27-'Cash Flow & Debt Schedule'!G21 -> 2.2665232
B11: Goodwill & Intangible Assets (Purchase Price Allocation, Plug) | C11: =(C15+'Sources & Uses'!C10)-C7-C8-C9-C10 -> 7.44356 | D11: =C11 -> 7.44356 | E11: =D11 -> 7.44356 | F11: =E11 -> 7.44356 | G11: =F11 -> 7.44356 | H11: =G11 -> 7.44356
B12: Total Assets | C12: =SUM(C7:C11) -> 12.28376 | D12: =SUM(D7:D11) -> 12.555033 | E12: =SUM(E7:E11) -> 13.002658 | F12: =SUM(F7:F11) -> 13.635484 | G12: =SUM(G7:G11) -> 14.462966 | H12: =SUM(H7:H11) -> 15.495204
B14: Liabilities
B15: Accounts Payable | C15: =('Income Statement'!G6-'Income Statement'!G9)*Assumptions!C68 -> 0.47376 | D15: =('Income Statement'!H6-'Income Statement'!H9)*Assumptions!C68 -> 0.4998168 | E15: =('Income Statement'!I6-'Income Statement'!I9)*Assumptions!C68 -> 0.52730672 | F15: =('Income Statement'!J6-'Income Statement'!J9)*Assumptions!C68 -> 0.55630859 | G15: =('Income Statement'!K6-'Income Statement'!K9)*Assumptions!C68 -> 0.58690557 | H15: =('Income Statement'!L6-'Income Statement'!L9)*Assumptions!C68 -> 0.61918537
B16: Senior Debt | C16: ='Sources & Uses'!C14 -> 5 | D16: ='Cash Flow & Debt Schedule'!C10 -> 4.1666667 | E16: ='Cash Flow & Debt Schedule'!D10 -> 3.3333333 | F16: ='Cash Flow & Debt Schedule'!E10 -> 2.5 | G16: ='Cash Flow & Debt Schedule'!F10 -> 1.6666667 | H16: ='Cash Flow & Debt Schedule'!G10 -> 0.83333333
B17: Seller Note | C17: ='Sources & Uses'!C15 -> 1.1 | D17: ='Cash Flow & Debt Schedule'!C15 -> 1.1 | E17: ='Cash Flow & Debt Schedule'!D15 -> 1.1 | F17: ='Cash Flow & Debt Schedule'!E15 -> 1.1 | G17: ='Cash Flow & Debt Schedule'!F15 -> 1.1 | H17: ='Cash Flow & Debt Schedule'!G15 -> 1.1
B18: Total Liabilities | C18: =SUM(C15:C17) -> 6.57376 | D18: =SUM(D15:D17) -> 5.7664835 | E18: =SUM(E15:E17) -> 4.9606401 | F18: =SUM(F15:F17) -> 4.1563086 | G18: =SUM(G15:G17) -> 3.3535722 | H18: =SUM(H15:H17) -> 2.5525187
B20: Equity
B21: Sponsor / Buyer Equity | C21: ='Sources & Uses'!C17 -> 4.06 | D21: ='Sources & Uses'!C17 -> 4.06 | E21: ='Sources & Uses'!C17 -> 4.06 | F21: ='Sources & Uses'!C17 -> 4.06 | G21: ='Sources & Uses'!C17 -> 4.06 | H21: ='Sources & Uses'!C17 -> 4.06
B22: Seller Equity Rollover | C22: ='Sources & Uses'!C16 -> 1.65 | D22: ='Sources & Uses'!C16 -> 1.65 | E22: ='Sources & Uses'!C16 -> 1.65 | F22: ='Sources & Uses'!C16 -> 1.65 | G22: ='Sources & Uses'!C16 -> 1.65 | H22: ='Sources & Uses'!C16 -> 1.65
B23: Retained Earnings | C23: 0 | D23: =C23+'Income Statement'!H18 -> 1.0785495 | E23: =D23+'Income Statement'!I18 -> 2.3320177 | F23: =E23+'Income Statement'!J18 -> 3.7691753 | G23: =F23+'Income Statement'!K18 -> 5.3993938 | H23: =G23+'Income Statement'!L18 -> 7.2326857
B24: Total Equity | C24: =SUM(C21:C23) -> 5.71 | D24: =SUM(D21:D23) -> 6.7885495 | E24: =SUM(E21:E23) -> 8.0420177 | F24: =SUM(F21:F23) -> 9.4791753 | G24: =SUM(G21:G23) -> 11.109394 | H24: =SUM(H21:H23) -> 12.942686
B26: Total Liabilities & Equity | C26: =C18+C24 -> 12.28376 | D26: =D18+D24 -> 12.555033 | E26: =E18+E24 -> 13.002658 | F26: =F18+F24 -> 13.635484 | G26: =G18+G24 -> 14.462966 | H26: =H18+H24 -> 15.495204
B27: Balance Check (Assets – Liabilities & Equity) | C27: =C12-C26 -> 0 | D27: =D12-D26 -> 0 | E27: =E12-E26 -> 0 | F27: =F12-F26 -> 0 | G27: =G12-G26 -> 0 | H27: =H12-H26 -> 0

Sheet Cash Flow & Debt Schedule
F1: STRICTLY CONFIDENTIAL
B2: CASH FLOW & DEBT SCHEDULE
B3: Post-Close Debt Amortization & Cash Flow, 2026E–2030E (Illustrative)
B5: ($M CAD) | C5: 2026E | D5: 2027E | E5: 2028E | F5: 2029E | G5: 2030E
B6: Senior Debt Schedule
B7: Beginning Balance | C7: ='Sources & Uses'!C14 -> 5 | D7: =C10 -> 4.1666667 | E7: =D10 -> 3.3333333 | F7: =E10 -> 2.5 | G7: =F10 -> 1.6666667
B8: Scheduled Amortization | C8: =-MIN(C7, $C$7/Assumptions!C75) -> -0.83333333 | D8: =-MIN(D7, $C$7/Assumptions!C75) -> -0.83333333 | E8: =-MIN(E7, $C$7/Assumptions!C75) -> -0.83333333 | F8: =-MIN(F7, $C$7/Assumptions!C75) -> -0.83333333 | G8: =-MIN(G7, $C$7/Assumptions!C75) -> -0.83333333
B9: Interest Expense | C9: =C7*Assumptions!C74 -> 0.4375 | D9: =D7*Assumptions!C74 -> 0.36458333 | E9: =E7*Assumptions!C74 -> 0.29166667 | F9: =F7*Assumptions!C74 -> 0.21875 | G9: =G7*Assumptions!C74 -> 0.14583333
B10: Ending Balance | C10: =C7+C8 -> 4.1666667 | D10: =D7+D8 -> 3.3333333 | E10: =E7+E8 -> 2.5 | F10: =F7+F8 -> 1.6666667 | G10: =G7+G8 -> 0.83333333
B12: Seller Note Schedule (Interest-Only, Bullet at Exit)
B13: Beginning Balance | C13: ='Sources & Uses'!C15 -> 1.1 | D13: =C15 -> 1.1 | E13: =D15 -> 1.1 | F13: =E15 -> 1.1 | G13: =F15 -> 1.1
B14: Interest Expense (Cash) | C14: =C13*Assumptions!C76 -> 0.088 | D14: =D13*Assumptions!C76 -> 0.088 | E14: =E13*Assumptions!C76 -> 0.088 | F14: =F13*Assumptions!C76 -> 0.088 | G14: =G13*Assumptions!C76 -> 0.088
B15: Ending Balance (flat, no amortization) | C15: =C13 -> 1.1 | D15: =D13 -> 1.1 | E15: =E13 -> 1.1 | F15: =F13 -> 1.1 | G15: =G13 -> 1.1
B17: Total Interest Expense (Senior Debt + Seller Note) | C17: =C9+C14 -> 0.5255 | D17: =D9+D14 -> 0.45258333 | E17: =E9+E14 -> 0.37966667 | F17: =F9+F14 -> 0.30675 | G17: =G9+G14 -> 0.23383333
B19: Cash Flow Statement
B20: Net Income | C20: ='Income Statement'!H18 -> 1.0785495 | D20: ='Income Statement'!I18 -> 1.2534682 | E20: ='Income Statement'!J18 -> 1.4371576 | F20: ='Income Statement'!K18 -> 1.6302185 | G20: ='Income Statement'!L18 -> 1.8332918
B21: (+) Depreciation & Amortization | C21: ='Income Statement'!H13 -> 0.29751 | D21: ='Income Statement'!I13 -> 0.31387305 | E21: ='Income Statement'!J13 -> 0.33113607 | F21: ='Income Statement'!K13 -> 0.34934855 | G21: ='Income Statement'!L13 -> 0.36856272
B22: (–) Increase in Accounts Receivable | C22: =-('Balance Sheet'!D8-'Balance Sheet'!C8) -> -0.06204 | D22: =-('Balance Sheet'!E8-'Balance Sheet'!D8) -> -0.0654522 | E22: =-('Balance Sheet'!F8-'Balance Sheet'!E8) -> -0.069052071 | F22: =-('Balance Sheet'!G8-'Balance Sheet'!F8) -> -0.072849935 | G22: =-('Balance Sheet'!H8-'Balance Sheet'!G8) -> -0.076856681
B23: (–) Increase in Inventory | C23: =-('Balance Sheet'!D9-'Balance Sheet'!C9) -> -0.032571 | D23: =-('Balance Sheet'!E9-'Balance Sheet'!D9) -> -0.034362405 | E23: =-('Balance Sheet'!F9-'Balance Sheet'!E9) -> -0.036252337 | F23: =-('Balance Sheet'!G9-'Balance Sheet'!F9) -> -0.038246216 | G23: =-('Balance Sheet'!H9-'Balance Sheet'!G9) -> -0.040349758
B24: (+) Increase in Accounts Payable | C24: =('Balance Sheet'!D15-'Balance Sheet'!C15) -> 0.0260568 | D24: =('Balance Sheet'!E15-'Balance Sheet'!D15) -> 0.027489924 | E24: =('Balance Sheet'!F15-'Balance Sheet'!E15) -> 0.02900187 | F24: =('Balance Sheet'!G15-'Balance Sheet'!F15) -> 0.030596973 | G24: =('Balance Sheet'!H15-'Balance Sheet'!G15) -> 0.032279806
B25: Cash Flow from Operations | C25: =SUM(C20:C24) -> 1.3075053 | D25: =SUM(D20:D24) -> 1.4950166 | E25: =SUM(E20:E24) -> 1.6919911 | F25: =SUM(F20:F24) -> 1.8990679 | G25: =SUM(G20:G24) -> 2.1169279
B27: Capital Expenditures | C27: =-'Income Statement'!H6*Assumptions!C65 -> -0.19834 | D27: =-'Income Statement'!I6*Assumptions!C65 -> -0.2092487 | E27: =-'Income Statement'!J6*Assumptions!C65 -> -0.22075738 | F27: =-'Income Statement'!K6*Assumptions!C65 -> -0.23289903 | G27: =-'Income Statement'!L6*Assumptions!C65 -> -0.24570848
B28: Cash Flow from Investing | C28: =C27 -> -0.19834 | D28: =D27 -> -0.2092487 | E28: =E27 -> -0.22075738 | F28: =F27 -> -0.23289903 | G28: =G27 -> -0.24570848
B30: Senior Debt Repayment | C30: =C8 -> -0.83333333 | D30: =D8 -> -0.83333333 | E30: =E8 -> -0.83333333 | F30: =F8 -> -0.83333333 | G30: =G8 -> -0.83333333
B31: Cash Flow from Financing | C31: =C30 -> -0.83333333 | D31: =D30 -> -0.83333333 | E31: =E30 -> -0.83333333 | F31: =F30 -> -0.83333333 | G31: =G30 -> -0.83333333
B33: Net Change in Cash | C33: =C25+C28+C31 -> 0.27583197 | D33: =D25+D28+D31 -> 0.45243456 | E33: =E25+E28+E31 -> 0.63790037 | F33: =F25+F28+F31 -> 0.83283554 | G33: =G25+G28+G31 -> 1.0378861
B34: Beginning Cash | C34: =Assumptions!C70 -> 0.3 | D34: =C35 -> 0.57583197 | E34: =D35 -> 1.0282665 | F34: =E35 -> 1.6661669 | G34: =F35 -> 2.4990024
B35: Ending Cash | C35: =C34+C33 -> 0.57583197 | D35: =D34+D33 -> 1.0282665 | E35: =E34+E33 -> 1.6661669 | F35: =F34+F33 -> 2.4990024 | G35: =G34+G33 -> 3.5368886

Sheet Valuation
F1: STRICTLY CONFIDENTIAL
B2: VALUATION
B3: Enterprise Value & Equity Value Build (Active Case)
B5: Enterprise Value Build
B6: Adjusted EBITDA (2025E) | C6: =Assumptions!C46 -> 2
B7: Selected EV / EBITDA Multiple (Active Case) | C7: =Assumptions!C51 -> 5.5
B8: Enterprise Value | C8: =C6*C7 -> 11
B9: Implied EV / 2025E Revenue | C9: =C8/Assumptions!C35 -> 1.1702128
B11: Cross-Check vs. CIM Indicative Range (p.16)
B12: Scenario | C12: Multiple | D12: Enterprise Value ($M)
B13: Low Case | C13: =Assumptions!C52 -> 4.5 | D13: =Assumptions!C46*Assumptions!C52 -> 9
B14: Active Case (selected) | C14: =C7 -> 5.5 | D14: =C8 -> 11
B15: High Case | C15: =Assumptions!C53 -> 6.5 | D15: =Assumptions!C46*Assumptions!C53 -> 13
B16: CIM-Disclosed Indicative Range | D16: $9.0M – $13.0M CAD
B18: Enterprise Value to Equity Value Bridge
B19: Enterprise Value | C19: =C8 -> 11
B20: (–) Net Debt at Close | C20: =-Assumptions!C54 -> 0
B21: Equity Value (100%) | C21: =C19+C20 -> 11

Sheet Sources & Uses
F1: STRICTLY CONFIDENTIAL
B2: SOURCES & USES
B3: Active Case Transaction Funding Structure
B5: Uses of Funds
B6: Use | C6: $M | D6: % of Total
B7: Enterprise Value (Purchase Price) | C7: =Valuation!C8 -> 11 | D7: =C7/C10 -> 0.93141406
B8: Advisor Success Fee | C8: ='Advisor Fee'!C18 -> 0.7 | D8: =C8/C10 -> 0.059271804
B9: Other Transaction Expenses | C9: =Assumptions!C60*C7 -> 0.11 | D9: =C9/C10 -> 0.0093141406
B10: Total Uses | C10: =SUM(C7:C9) -> 11.81
B12: Sources of Funds
B13: Source | C13: $M | D13: % of Total
B14: Senior Debt | C14: =Assumptions!C57*Assumptions!C46 -> 5 | D14: =C14/C18 -> 0.42337003
B15: Seller Note | C15: =Assumptions!C58*C7 -> 1.1 | D15: =C15/C18 -> 0.093141406
B16: Seller Equity Rollover | C16: =Assumptions!C59*C7 -> 1.65 | D16: =C16/C18 -> 0.13971211
B17: Sponsor / Buyer New Equity (Plug) | C17: =C10-C14-C15-C16 -> 4.06 | D17: =C17/C18 -> 0.34377646
B18: Total Sources | C18: =SUM(C14:C17) -> 11.81
B20: Check (Sources – Uses) | C20: =C18-C10 -> 0
B22: Capital Structure Ratios
B23: Senior Debt / Adjusted EBITDA (Leverage Check) | C23: =C14/Assumptions!C46 -> 2.5
B24: Sponsor Equity / Total Sources | C24: =C17/C18 -> 0.34377646
B25: Seller Continuing Interest (Note + Rollover) / EV | C25: =(C15+C16)/C7 -> 0.25

Sheet Advisor Fee
F1: STRICTLY CONFIDENTIAL
B2: ADVISOR SUCCESS FEE
B3: Modified Lehman Formula, Applied to Transaction Value
B5: Transaction Value (Basis = Enterprise Value) | C5: =Valuation!C8 -> 11
B7: Modified Lehman Fee Tier Schedule
B8: Tier | C8: From ($M) | D8: To ($M) | E8: Rate (%) | F8: Applicable Base ($M) | G8: Tier Fee ($M)
B9: =Assumptions!B81 -> Tier 1 | C9: =Assumptions!C81 -> 0 | D9: =Assumptions!D81 -> 5 | E9: =Assumptions!E81 -> 0.07 | F9: =MIN(MAX(C5-C9,0),D9-C9) -> 5 | G9: =F9*E9 -> 0.35
B10: =Assumptions!B82 -> Tier 2 | C10: =Assumptions!C82 -> 5 | D10: =Assumptions!D82 -> 10 | E10: =Assumptions!E82 -> 0.06 | F10: =MIN(MAX(C5-C10,0),D10-C10) -> 5 | G10: =F10*E10 -> 0.3
B11: =Assumptions!B83 -> Tier 3 | C11: =Assumptions!C83 -> 10 | D11: =Assumptions!D83 -> 15 | E11: =Assumptions!E83 -> 0.05 | F11: =MIN(MAX(C5-C11,0),D11-C11) -> 1 | G11: =F11*E11 -> 0.05
B12: =Assumptions!B84 -> Tier 4 | C12: =Assumptions!C84 -> 15 | D12: =Assumptions!D84 -> 20 | E12: =Assumptions!E84 -> 0.04 | F12: =MIN(MAX(C5-C12,0),D12-C12) -> 0 | G12: =F12*E12 -> 0
B13: =Assumptions!B85 -> Tier 5 (> $20.0M) | C13: =Assumptions!C85 -> 20 | D13: =Assumptions!D85 -> 9999 | E13: =Assumptions!E85 -> 0.03 | F13: =MIN(MAX(C5-C13,0),D13-C13) -> 0 | G13: =F13*E13 -> 0
B14: Total Tiered Fee | F14: =SUM(F9:F13) -> 13 | G14: =SUM(G9:G13) -> 0.7
B16: Fee Floor Check & Final Fee
B17: Minimum Fee Floor | C17: =Assumptions!C86 -> 0.25
B18: Advisor Fee (Greater of Tiered Fee or Minimum Floor) | C18: =MAX(G14,C17) -> 0.7
B19: Advisor Fee (% of Transaction Value, Blended/Effective Rate) | C19: =C18/C5 -> 0.063636364
B20: Advisor Fee ($, actual dollars) | C20: =C18*1000000 -> 700000

Sheet Sensitivity
F1: STRICTLY CONFIDENTIAL
B2: SENSITIVITY ANALYSIS
B3: EV / EBITDA Multiple → Enterprise Value → Advisor Fee
B5: Sensitivity Table (Adjusted EBITDA held constant at 2025E entry level) | J5: Supporting Fee Tier Build (non-array; mirrors Advisor Fee sheet)
B6: EV / EBITDA Multiple | C6: Adj. EBITDA ($M) | D6: Enterprise Value ($M) | E6: Advisor Fee ($M) | F6: Advisor Fee (%) | G6: Equity Value ($M) | J6: Tier 1 Fee | K6: Tier 2 Fee | L6: Tier 3 Fee | M6: Tier 4 Fee | N6: Tier 5 Fee | O6: Tiered Total | P6: Final Fee (w/ floor)
B7: 4.5 | C7: =Assumptions!C46 -> 2 | D7: =B7*C7 -> 9 | E7: =P7 -> 0.59 | F7: =E7/D7 -> 0.065555556 | G7: =D7-Assumptions!C54 -> 9 | J7: =MIN(MAX($D7-Assumptions!$C$81,0),Assumptions!$D$81-Assumptions!$C$81)*Assumptions!$E$81 -> 0.35 | K7: =MIN(MAX($D7-Assumptions!$C$82,0),Assumptions!$D$82-Assumptions!$C$82)*Assumptions!$E$82 -> 0.24 | L7: =MIN(MAX($D7-Assumptions!$C$83,0),Assumptions!$D$83-Assumptions!$C$83)*Assumptions!$E$83 -> 0 | M7: =MIN(MAX($D7-Assumptions!$C$84,0),Assumptions!$D$84-Assumptions!$C$84)*Assumptions!$E$84 -> 0 | N7: =MIN(MAX($D7-Assumptions!$C$85,0),Assumptions!$D$85-Assumptions!$C$85)*Assumptions!$E$85 -> 0 | O7: =SUM(J7:N7) -> 0.59 | P7: =MAX(O7,Assumptions!C86) -> 0.59
B8: 4.75 | C8: =Assumptions!C46 -> 2 | D8: =B8*C8 -> 9.5 | E8: =P8 -> 0.62 | F8: =E8/D8 -> 0.065263158 | G8: =D8-Assumptions!C54 -> 9.5 | J8: =MIN(MAX($D8-Assumptions!$C$81,0),Assumptions!$D$81-Assumptions!$C$81)*Assumptions!$E$81 -> 0.35 | K8: =MIN(MAX($D8-Assumptions!$C$82,0),Assumptions!$D$82-Assumptions!$C$82)*Assumptions!$E$82 -> 0.27 | L8: =MIN(MAX($D8-Assumptions!$C$83,0),Assumptions!$D$83-Assumptions!$C$83)*Assumptions!$E$83 -> 0 | M8: =MIN(MAX($D8-Assumptions!$C$84,0),Assumptions!$D$84-Assumptions!$C$84)*Assumptions!$E$84 -> 0 | N8: =MIN(MAX($D8-Assumptions!$C$85,0),Assumptions!$D$85-Assumptions!$C$85)*Assumptions!$E$85 -> 0 | O8: =SUM(J8:N8) -> 0.62 | P8: =MAX(O8,Assumptions!C86) -> 0.62
B9: 5 | C9: =Assumptions!C46 -> 2 | D9: =B9*C9 -> 10 | E9: =P9 -> 0.65 | F9: =E9/D9 -> 0.065 | G9: =D9-Assumptions!C54 -> 10 | J9: =MIN(MAX($D9-Assumptions!$C$81,0),Assumptions!$D$81-Assumptions!$C$81)*Assumptions!$E$81 -> 0.35 | K9: =MIN(MAX($D9-Assumptions!$C$82,0),Assumptions!$D$82-Assumptions!$C$82)*Assumptions!$E$82 -> 0.3 | L9: =MIN(MAX($D9-Assumptions!$C$83,0),Assumptions!$D$83-Assumptions!$C$83)*Assumptions!$E$83 -> 0 | M9: =MIN(MAX($D9-Assumptions!$C$84,0),Assumptions!$D$84-Assumptions!$C$84)*Assumptions!$E$84 -> 0 | N9: =MIN(MAX($D9-Assumptions!$C$85,0),Assumptions!$D$85-Assumptions!$C$85)*Assumptions!$E$85 -> 0 | O9: =SUM(J9:N9) -> 0.65 | P9: =MAX(O9,Assumptions!C86) -> 0.65
B10: 5.25 | C10: =Assumptions!C46 -> 2 | D10: =B10*C10 -> 10.5 | E10: =P10 -> 0.675 | F10: =E10/D10 -> 0.064285714 | G10: =D10-Assumptions!C54 -> 10.5 | J10: =MIN(MAX($D10-Assumptions!$C$81,0),Assumptions!$D$81-Assumptions!$C$81)*Assumptions!$E$81 -> 0.35 | K10: =MIN(MAX($D10-Assumptions!$C$82,0),Assumptions!$D$82-Assumptions!$C$82)*Assumptions!$E$82 -> 0.3 | L10: =MIN(MAX($D10-Assumptions!$C$83,0),Assumptions!$D$83-Assumptions!$C$83)*Assumptions!$E$83 -> 0.025 | M10: =MIN(MAX($D10-Assumptions!$C$84,0),Assumptions!$D$84-Assumptions!$C$84)*Assumptions!$E$84 -> 0 | N10: =MIN(MAX($D10-Assumptions!$C$85,0),Assumptions!$D$85-Assumptions!$C$85)*Assumptions!$E$85 -> 0 | O10: =SUM(J10:N10) -> 0.675 | P10: =MAX(O10,Assumptions!C86) -> 0.675
B11: 5.5 | C11: =Assumptions!C46 -> 2 | D11: =B11*C11 -> 11 | E11: =P11 -> 0.7 | F11: =E11/D11 -> 0.063636364 | G11: =D11-Assumptions!C54 -> 11 | J11: =MIN(MAX($D11-Assumptions!$C$81,0),Assumptions!$D$81-Assumptions!$C$81)*Assumptions!$E$81 -> 0.35 | K11: =MIN(MAX($D11-Assumptions!$C$82,0),Assumptions!$D$82-Assumptions!$C$82)*Assumptions!$E$82 -> 0.3 | L11: =MIN(MAX($D11-Assumptions!$C$83,0),Assumptions!$D$83-Assumptions!$C$83)*Assumptions!$E$83 -> 0.05 | M11: =MIN(MAX($D11-Assumptions!$C$84,0),Assumptions!$D$84-Assumptions!$C$84)*Assumptions!$E$84 -> 0 | N11: =MIN(MAX($D11-Assumptions!$C$85,0),Assumptions!$D$85-Assumptions!$C$85)*Assumptions!$E$85 -> 0 | O11: =SUM(J11:N11) -> 0.7 | P11: =MAX(O11,Assumptions!C86) -> 0.7
B12: 5.75 | C12: =Assumptions!C46 -> 2 | D12: =B12*C12 -> 11.5 | E12: =P12 -> 0.725 | F12: =E12/D12 -> 0.063043478 | G12: =D12-Assumptions!C54 -> 11.5 | J12: =MIN(MAX($D12-Assumptions!$C$81,0),Assumptions!$D$81-Assumptions!$C$81)*Assumptions!$E$81 -> 0.35 | K12: =MIN(MAX($D12-Assumptions!$C$82,0),Assumptions!$D$82-Assumptions!$C$82)*Assumptions!$E$82 -> 0.3 | L12: =MIN(MAX($D12-Assumptions!$C$83,0),Assumptions!$D$83-Assumptions!$C$83)*Assumptions!$E$83 -> 0.075 | M12: =MIN(MAX($D12-Assumptions!$C$84,0),Assumptions!$D$84-Assumptions!$C$84)*Assumptions!$E$84 -> 0 | N12: =MIN(MAX($D12-Assumptions!$C$85,0),Assumptions!$D$85-Assumptions!$C$85)*Assumptions!$E$85 -> 0 | O12: =SUM(J12:N12) -> 0.725 | P12: =MAX(O12,Assumptions!C86) -> 0.725
B13: 6 | C13: =Assumptions!C46 -> 2 | D13: =B13*C13 -> 12 | E13: =P13 -> 0.75 | F13: =E13/D13 -> 0.0625 | G13: =D13-Assumptions!C54 -> 12 | J13: =MIN(MAX($D13-Assumptions!$C$81,0),Assumptions!$D$81-Assumptions!$C$81)*Assumptions!$E$81 -> 0.35 | K13: =MIN(MAX($D13-Assumptions!$C$82,0),Assumptions!$D$82-Assumptions!$C$82)*Assumptions!$E$82 -> 0.3 | L13: =MIN(MAX($D13-Assumptions!$C$83,0),Assumptions!$D$83-Assumptions!$C$83)*Assumptions!$E$83 -> 0.1 | M13: =MIN(MAX($D13-Assumptions!$C$84,0),Assumptions!$D$84-Assumptions!$C$84)*Assumptions!$E$84 -> 0 | N13: =MIN(MAX($D13-Assumptions!$C$85,0),Assumptions!$D$85-Assumptions!$C$85)*Assumptions!$E$85 -> 0 | O13: =SUM(J13:N13) -> 0.75 | P13: =MAX(O13,Assumptions!C86) -> 0.75
B14: 6.25 | C14: =Assumptions!C46 -> 2 | D14: =B14*C14 -> 12.5 | E14: =P14 -> 0.775 | F14: =E14/D14 -> 0.062 | G14: =D14-Assumptions!C54 -> 12.5 | J14: =MIN(MAX($D14-Assumptions!$C$81,0),Assumptions!$D$81-Assumptions!$C$81)*Assumptions!$E$81 -> 0.35 | K14: =MIN(MAX($D14-Assumptions!$C$82,0),Assumptions!$D$82-Assumptions!$C$82)*Assumptions!$E$82 -> 0.3 | L14: =MIN(MAX($D14-Assumptions!$C$83,0),Assumptions!$D$83-Assumptions!$C$83)*Assumptions!$E$83 -> 0.125 | M14: =MIN(MAX($D14-Assumptions!$C$84,0),Assumptions!$D$84-Assumptions!$C$84)*Assumptions!$E$84 -> 0 | N14: =MIN(MAX($D14-Assumptions!$C$85,0),Assumptions!$D$85-Assumptions!$C$85)*Assumptions!$E$85 -> 0 | O14: =SUM(J14:N14) -> 0.775 | P14: =MAX(O14,Assumptions!C86) -> 0.775
B15: 6.5 | C15: =Assumptions!C46 -> 2 | D15: =B15*C15 -> 13 | E15: =P15 -> 0.8 | F15: =E15/D15 -> 0.061538462 | G15: =D15-Assumptions!C54 -> 13 | J15: =MIN(MAX($D15-Assumptions!$C$81,0),Assumptions!$D$81-Assumptions!$C$81)*Assumptions!$E$81 -> 0.35 | K15: =MIN(MAX($D15-Assumptions!$C$82,0),Assumptions!$D$82-Assumptions!$C$82)*Assumptions!$E$82 -> 0.3 | L15: =MIN(MAX($D15-Assumptions!$C$83,0),Assumptions!$D$83-Assumptions!$C$83)*Assumptions!$E$83 -> 0.15 | M15: =MIN(MAX($D15-Assumptions!$C$84,0),Assumptions!$D$84-Assumptions!$C$84)*Assumptions!$E$84 -> 0 | N15: =MIN(MAX($D15-Assumptions!$C$85,0),Assumptions!$D$85-Assumptions!$C$85)*Assumptions!$E$85 -> 0 | O15: =SUM(J15:N15) -> 0.8 | P15: =MAX(O15,Assumptions!C86) -> 0.8
B19: Range Summary
B20: Low (4.50x) Enterprise Value | D20: =D7 -> 9
B21: High (6.50x) Enterprise Value | D21: =D15 -> 13
B22: Low (4.50x) Advisor Fee | D22: =E7 -> 0.59
B23: High (6.50x) Advisor Fee | D23: =E15 -> 0.8

Sheet Returns Analysis
F1: STRICTLY CONFIDENTIAL
B2: RETURNS ANALYSIS
B3: Illustrative Buyer (Sponsor) Returns — 5-Year Hold, Active Case
B5: Entry (2025E / Close)
B6: Sponsor Equity Investment | C6: ='Sources & Uses'!C17 -> 4.06
B7: Seller Equity Rollover (Co-Invest) | C7: ='Sources & Uses'!C16 -> 1.65
B8: Entry EV / EBITDA Multiple (Active Case) | C8: =Assumptions!C51 -> 5.5
B10: Exit (2030E / Year 5)
B11: Exit EBITDA (2030E, Active Case) | C11: ='Income Statement'!L11 -> 3.0467852
B12: Exit Multiple (assumed = entry multiple; no expansion/contraction) | C12: =Assumptions!C51 -> 5.5
B13: Exit Enterprise Value | C13: =C11*C12 -> 16.757318
B14: (–) Exit Senior Debt Outstanding | C14: =-'Cash Flow & Debt Schedule'!G10 -> -0.83333333
B15: (–) Exit Seller Note Outstanding | C15: =-'Cash Flow & Debt Schedule'!G15 -> -1.1
B16: Exit Equity Value | C16: =C13+C14+C15 -> 14.823985
B18: Sponsor Proceeds & Returns
B19: Sponsor Ownership % (of Total Equity at Close) | C19: =C6/(C6+C7) -> 0.71103327
B20: Sponsor Exit Proceeds | C20: =C16*C19 -> 10.540347
B22: MOIC (Multiple of Invested Capital) | C22: =C20/C6 -> 2.5961445
B23: Holding Period (Years) | C23: 5
B24: IRR (Internal Rate of Return) | C24: =IRR(C28:H28) -> 0.21022403
B26: Sponsor Cash Flow (for IRR calculation)
B27: Year | C27: Year 0 (Close) | D27: Year 1 | E27: Year 2 | F27: Year 3 | G27: Year 4 | H27: Year 5 (Exit)
B28: Sponsor Cash Flow ($M) | C28: =-C6 -> -4.06 | D28: 0 | E28: 0 | F28: 0 | G28: 0 | H28: =C20 -> 10.540347
