Workbook

Sheet Dashboard
B2: PROJECT IRONBEND
B3: Deal Process Tracker | Northline Precision Pipe Bending & Fabrication Ltd.
F6: Report date: | I6: 46244
B8: BUYERS IN UNIVERSE | D8: NDAs SIGNED | F8: CIMs SENT | H8: IOIs RECEIVED | J8: MGMT MEETINGS HELD
B9: =COUNTA('Buyer Tracker'!B4:B141) -> 138 | D9: =COUNT('Buyer Tracker'!$J$4:$J$141) -> 70 | F9: =COUNT('Buyer Tracker'!$K$4:$K$141) -> 70 | H9: =COUNT('Buyer Tracker'!$L$4:$L$141) -> 23 | J9: =COUNT('Buyer Tracker'!$O$4:$O$141) -> 13
B10: Newly sourced from buyer-universe research — not yet contacted: | G10: =COUNTIF('Buyer Tracker'!$U$4:$U$141,"Not Contacted")&" buyers" -> 16 buyers | I10: See Buyer Universe tab →
B11: DEAL FUNNEL — BUYERS REACHING EACH STAGE (LIVE, LINKED TO BUYER TRACKER)
B12: 1. Teaser | C12: 2. NDA | D12: 3. CIM Sent | E12: 4. IOI Received | F12: 5. Mgmt Meeting | G12: 6. LOI Signed | H12: 7. Diligence | I12: 8. Definitive Agmt | J12: 9. Close
B13: =COUNT('Buyer Tracker'!$I$4:$I$141) -> 122 | C13: =COUNT('Buyer Tracker'!$J$4:$J$141) -> 70 | D13: =COUNT('Buyer Tracker'!$K$4:$K$141) -> 70 | E13: =COUNT('Buyer Tracker'!$L$4:$L$141) -> 23 | F13: =COUNT('Buyer Tracker'!$O$4:$O$141) -> 13 | G13: =COUNT('Buyer Tracker'!$P$4:$P$141) -> 1 | H13: =COUNT('Buyer Tracker'!$Q$4:$Q$141) -> 1 | I13: =COUNT('Buyer Tracker'!$S$4:$S$141) -> 0 | J13: =COUNT('Buyer Tracker'!$T$4:$T$141) -> 0
B14: buyers | C14: =IFERROR(C13/B13,0) -> 0.57377049 | D14: =IFERROR(D13/C13,0) -> 1 | E14: =IFERROR(E13/D13,0) -> 0.32857143 | F14: =IFERROR(F13/E13,0) -> 0.56521739 | G14: =IFERROR(G13/F13,0) -> 0.076923077 | H14: =IFERROR(H13/G13,0) -> 1 | I14: =IFERROR(I13/H13,0) -> 0 | J14: =IFERROR(J13/I13,0) -> 0
B16: PIPELINE STATUS (LIVE)
B17: Active (incl. Exclusivity) | D17: =COUNTIF('Buyer Tracker'!$U$4:$U$141,"Active*") -> 1 | E17: Declined / Passed | G17: =COUNTIF('Buyer Tracker'!$U$4:$U$141,"Declined")+COUNTIF('Buyer Tracker'!$U$4:$U$141,"Passed") -> 93 | H17: Not Contacted / No Resp. / On Hold | J17: =COUNTIF('Buyer Tracker'!$U$4:$U$141,"No Response")+COUNTIF('Buyer Tracker'!$U$4:$U$141,"On Hold")+COUNTIF('Buyer Tracker'!$U$4:$U$141,"Not Contacted") -> 44
B19: INDICATIVE VALUATION RANGE FROM IOIs RECEIVED (LIVE)
B20: Low ($mm) | D20: =IFERROR(MIN('Buyer Tracker'!$M$4:$M$141),"n/a") -> 7 | E20: Average ($mm) | G20: =IFERROR((AVERAGE('Buyer Tracker'!$M$4:$M$141)+AVERAGE('Buyer Tracker'!$N$4:$N$141))/2,"n/a") -> 10.658696 | H20: High ($mm) | J20: =IFERROR(MAX('Buyer Tracker'!$N$4:$N$141),"n/a") -> 13.7
B22: OVERALL DEAL MILESTONE TIMELINE — PROJECT IRONBEND
B23: # | C23: Milestone | F23: Target Date | G23: Actual Date | H23: Status
B24: 1 | C24: Teaser | F24: 46083 | G24: 46083 | H24: Complete
B25: 2 | C25: NDA | F25: 46097 | G25: 46106 | H25: Complete
B26: 3 | C26: CIM Sent | F26: 46127 | G26: 46127 | H26: Complete
B27: 4 | C27: IOI Received | F27: 46188 | G27: 46191 | H27: Complete
B28: 5 | C28: Management Meeting | F28: 46218 | G28: 46221 | H28: Complete
B29: 6 | C29: LOI Signed | F29: 46223 | G29: 46224 | H29: Complete
B30: 7 | C30: Diligence Checklist | F30: 46276 | G30: — | H30: In Progress
B31: 8 | C31: Definitive Agreement | F31: 46283 | G31: — | H31: Not Started
B32: 9 | C32: Close | F32: 46326 | G32: — | H32: Not Started
B34: ="Current stage: 7 — Diligence (in progress, "&COUNTIF('Diligence Checklist'!E4:E29,"Complete")&" of "&COUNTA('Diligence Checklist'!E4:E29)&" items complete). Lead buyer B001 under 60-day exclusivity from 21-Jul-2026 (to 19-Sep-2026); definitive agreement targeted 18-Sep-2026, close 31-Oct-2026." -> Current stage: 7 — Diligence (in progress, 9 of 26 items complete). Lead buyer B001 under 60-day exclusivity from 21-Jul-2026 (to 19-Sep-2026); definitive agreement targeted 18-Sep-2026, close 31-Oct-2026.
B36: This dashboard is fully linked to the Buyer Tracker tab — funnel counts, status mix, IOI range and the current-stage line recalculate automatically as tracker rows are updated. Manual inputs: the report date (top right) and the milestone table (Target/Actual Date, Status). See the Instructions tab.
B38: VISUAL SUMMARY — LIVE CHARTS (LINKED TO BUYER TRACKER)
B56: Chart source data (auto — mirrors the boxes above; do not edit)
B57: Active | C57: =D17 -> 1 | E57: Low | F57: =D20 -> 7
B58: Declined / Passed | C58: =G17 -> 93 | E58: Average | F58: =G20 -> 10.658696
B59: Not Contacted / Other | C59: =J17 -> 44 | E59: High | F59: =J20 -> 13.7

Sheet Buyer Tracker
A1: BUYER TRACKER — PROJECT IRONBEND
A2: 138 buyers in universe (122 contacted with the blind teaser + 16 newly sourced, not yet contacted) | Snapshot as of the Dashboard report date | Columns I–T = process dates (edit as milestones occur) | Column V (Current Stage) and W (Days Since Update) calculate automatically — do not edit | Column U (Status) is a dropdown
A3: Buyer ID | B3: Buyer Name | C3: Type | D3: Priority | E3: Primary Contact | F3: Email | G3: Initial Outreach | H3: NDA Sent | I3: 1. Teaser Sent | J3: 2. NDA Signed | K3: 3. CIM Sent | L3: 4. IOI Received | M3: IOI Low ($mm) | N3: IOI High ($mm) | O3: 5. Mgmt Meeting | P3: 6. LOI Signed | Q3: 7. Diligence Start | R3: Diligence % | S3: 8. Definitive Agmt | T3: 9. Close Date | U3: Status | V3: Current Stage (auto) | W3: Days Since Update | X3: Notes
A4: B001 | B4: Ridgemont Buyout Partners | C4: Private Equity | D4: B | E4: Mark Choudhury | F4: m.choudhury@ridgemont.com | G4: 46107 | H4: 46111 | I4: 46107 | J4: 46117 | K4: 46125 | L4: 46171 | M4: 11.6 | N4: 13.4 | O4: 46210 | P4: 46224 | Q4: 46231 | R4: ='Diligence Checklist'!F32 -> 0.34615385 | U4: Active - Exclusivity | V4: =IF(T4<>"","9 - Closed",IF(S4<>"","8 - Definitive Agreement",IF(Q4<>"","7 - Diligence",IF(P4<>"","6 - LOI Signed",IF(O4<>"","5 - Mgmt Meeting",IF(L4<>"","4 - IOI Received",IF(K4<>"","3 - CIM Sent",IF(J4<>"","2 - NDA Signed",IF(I4<>"","1 - Teaser Sent","0 - Not Contacted"))))))))) -> 7 - Diligence | W4: =IF(COUNT(G4:T4)=0,"-",Dashboard!$I$6-MAX(G4:T4)) -> 13 | X4: Selected buyer: LOI countersigned 21-Jul-2026 (60-day exclusivity to 19-Sep-2026); confirmatory diligence since 28-Jul-2026, see Diligence Checklist.
A5: B002 | B5: Wexford Growth Partners | C5: Private Equity | D5: B | E5: Matthew MacAllister | F5: m.macallister@wexford.com | G5: 46091 | H5: 46095 | I5: 46091 | J5: 46105 | K5: 46113 | L5: 46145 | M5: 12.4 | N5: 13.6 | O5: 46203 | U5: On Hold | V5: =IF(T5<>"","9 - Closed",IF(S5<>"","8 - Definitive Agreement",IF(Q5<>"","7 - Diligence",IF(P5<>"","6 - LOI Signed",IF(O5<>"","5 - Mgmt Meeting",IF(L5<>"","4 - IOI Received",IF(K5<>"","3 - CIM Sent",IF(J5<>"","2 - NDA Signed",IF(I5<>"","1 - Teaser Sent","0 - Not Contacted"))))))))) -> 5 - Mgmt Meeting | W5: =IF(COUNT(G5:T5)=0,"-",Dashboard!$I$6-MAX(G5:T5)) -> 41 | X5: Final-round bidder: submitted a competing LOI on 21-Jul-2026 that was not countersigned (weaker certainty of financing). Backup bidder; on hold during B001 exclusivity.
A6: B003 | B6: Silverpeak Growth Partners | C6: Private Equity | D6: C | E6: Daniel Bergeron | F6: d.bergeron@silverpeak.com | G6: 46090 | H6: 46093 | I6: 46090 | J6: 46101 | K6: 46112 | L6: 46149 | M6: 12 | N6: 12.8 | O6: 46214 | U6: On Hold | V6: =IF(T6<>"","9 - Closed",IF(S6<>"","8 - Definitive Agreement",IF(Q6<>"","7 - Diligence",IF(P6<>"","6 - LOI Signed",IF(O6<>"","5 - Mgmt Meeting",IF(L6<>"","4 - IOI Received",IF(K6<>"","3 - CIM Sent",IF(J6<>"","2 - NDA Signed",IF(I6<>"","1 - Teaser Sent","0 - Not Contacted"))))))))) -> 5 - Mgmt Meeting | W6: =IF(COUNT(G6:T6)=0,"-",Dashboard!$I$6-MAX(G6:T6)) -> 30 | X6: Final-round bidder after management meeting; did not submit an LOI by the 21-Jul deadline. On hold during B001 exclusivity.
A7: B004 | B7: Cedarbrook Growth Partners | C7: Family Office | D7: B | E7: Thomas Osei | F7: t.osei@cedarbrook.com | G7: 46100 | H7: 46104 | I7: 46100 | J7: 46108 | K7: 46119 | L7: 46169 | M7: 9 | N7: 10.2 | O7: 46219 | U7: Declined | V7: =IF(T7<>"","9 - Closed",IF(S7<>"","8 - Definitive Agreement",IF(Q7<>"","7 - Diligence",IF(P7<>"","6 - LOI Signed",IF(O7<>"","5 - Mgmt Meeting",IF(L7<>"","4 - IOI Received",IF(K7<>"","3 - CIM Sent",IF(J7<>"","2 - NDA Signed",IF(I7<>"","1 - Teaser Sent","0 - Not Contacted"))))))))) -> 5 - Mgmt Meeting | W7: =IF(COUNT(G7:T7)=0,"-",Dashboard!$I$6-MAX(G7:T7)) -> 25 | X7: Declined to proceed after review — cited valuation gap.
A8: B005 | B8: Kestrel Private Equity | C8: Private Equity | D8: A | E8: Michael Nakamura | F8: m.nakamura@kestrel.com | G8: 46095 | H8: 46098 | I8: 46095 | J8: 46103 | K8: 46110 | L8: 46166 | M8: 9 | N8: 10.6 | O8: 46221 | U8: Declined | V8: =IF(T8<>"","9 - Closed",IF(S8<>"","8 - Definitive Agreement",IF(Q8<>"","7 - Diligence",IF(P8<>"","6 - LOI Signed",IF(O8<>"","5 - Mgmt Meeting",IF(L8<>"","4 - IOI Received",IF(K8<>"","3 - CIM Sent",IF(J8<>"","2 - NDA Signed",IF(I8<>"","1 - Teaser Sent","0 - Not Contacted"))))))))) -> 5 - Mgmt Meeting | W8: =IF(COUNT(G8:T8)=0,"-",Dashboard!$I$6-MAX(G8:T8)) -> 23 | X8: Declined to proceed after review — cited valuation gap.
A9: B006 | B9: Kestrel Industrial Capital | C9: Private Equity | D9: C | E9: Jason Nakamura | F9: j.nakamura@kestrel.com | G9: 46085 | H9: 46089 | I9: 46085 | J9: 46097 | K9: 46102 | L9: 46185 | M9: 13 | N9: 13.7 | O9: 46216 | U9: On Hold | V9: =IF(T9<>"","9 - Closed",IF(S9<>"","8 - Definitive Agreement",IF(Q9<>"","7 - Diligence",IF(P9<>"","6 - LOI Signed",IF(O9<>"","5 - Mgmt Meeting",IF(L9<>"","4 - IOI Received",IF(K9<>"","3 - CIM Sent",IF(J9<>"","2 - NDA Signed",IF(I9<>"","1 - Teaser Sent","0 - Not Contacted"))))))))) -> 5 - Mgmt Meeting | W9: =IF(COUNT(G9:T9)=0,"-",Dashboard!$I$6-MAX(G9:T9)) -> 28 | X9: Final-round bidder after management meeting; did not submit an LOI by the 21-Jul deadline. On hold during B001 exclusivity.
A10: B007 | B10: Stonegate Metalworks | C10: Strategic | D10: B | E10: Amanda Sorensen | F10: a.sorensen@stonegate.com | G10: 46097 | H10: 46101 | I10: 46097 | J10: 46104 | K10: 46115 | L10: 46135 | M10: 11.3 | N10: 12.3 | O10: 46204 | U10: Declined | V10: =IF(T10<>"","9 - Closed",IF(S10<>"","8 - Definitive Agreement",IF(Q10<>"","7 - Diligence",IF(P10<>"","6 - LOI Signed",IF(O10<>"","5 - Mgmt Meeting",IF(L10<>"","4 - IOI Received",IF(K10<>"","3 - CIM Sent",IF(J10<>"","2 - NDA Signed",IF(I10<>"","1 - Teaser Sent","0 - Not Contacted"))))))))) -> 5 - Mgmt Meeting | W10: =IF(COUNT(G10:T10)=0,"-",Dashboard!$I$6-MAX(G10:T10)) -> 40 | X10: Declined to proceed after review — cited valuation gap.
A11: B008 | B11: Deerfield Fabrication Group | C11: Strategic | D11: B | E11: Amanda Novak | F11: a.novak@deerfield.com | G11: 46096 | H11: 46099 | I11: 46096 | J11: 46106 | K11: 46116 | L11: 46177 | M11: 7.5 | N11: 8.4 | O11: 46219 | U11: On Hold | V11: =IF(T11<>"","9 - Closed",IF(S11<>"","8 - Definitive Agreement",IF(Q11<>"","7 - Diligence",IF(P11<>"","6 - LOI Signed",IF(O11<>"","5 - Mgmt Meeting",IF(L11<>"","4 - IOI Received",IF(K11<>"","3 - CIM Sent",IF(J11<>"","2 - NDA Signed",IF(I11<>"","1 - Teaser Sent","0 - Not Contacted"))))))))) -> 5 - Mgmt Meeting | W11: =IF(COUNT(G11:T11)=0,"-",Dashboard!$I$6-MAX(G11:T11)) -> 25 | X11: Final-round bidder after management meeting; did not submit an LOI by the 21-Jul deadline. On hold during B001 exclusivity.
A12: B009 | B12: Larkspur Capital Management | C12: Private Equity | D12: C | E12: Christopher Lindqvist | F12: c.lindqvist@larkspur.com | G12: 46105 | H12: 46109 | I12: 46105 | J12: 46119 | K12: 46122 | L12: 46157 | M12: 10.5 | N12: 12.2 | O12: 46209 | U12: Declined | V12: =IF(T12<>"","9 - Closed",IF(S12<>"","8 - Definitive Agreement",IF(Q12<>"","7 - Diligence",IF(P12<>"","6 - LOI Signed",IF(O12<>"","5 - Mgmt Meeting",IF(L12<>"","4 - IOI Received",IF(K12<>"","3 - CIM Sent",IF(J12<>"","2 - NDA Signed",IF(I12<>"","1 - Teaser Sent","0 - Not Contacted"))))))))) -> 5 - Mgmt Meeting | W12: =IF(COUNT(G12:T12)=0,"-",Dashboard!$I$6-MAX(G12:T12)) -> 35 | X12: Declined to proceed after review — cited valuation gap.
A13: B010 | B13: Highfield Equity Partners | C13: Family Office | D13: C | E13: James Okafor | F13: j.okafor@highfield.com | G13: 46101 | H13: 46105 | I13: 46101 | J13: 46108 | K13: 46113 | L13: 46161 | M13: 8.1 | N13: 8.9 | O13: 46196 | U13: Declined | V13: =IF(T13<>"","9 - Closed",IF(S13<>"","8 - Definitive Agreement",IF(Q13<>"","7 - Diligence",IF(P13<>"","6 - LOI Signed",IF(O13<>"","5 - Mgmt Meeting",IF(L13<>"","4 - IOI Received",IF(K13<>"","3 - CIM Sent",IF(J13<>"","2 - NDA Signed",IF(I13<>"","1 - Teaser Sent","0 - Not Contacted"))))))))) -> 5 - Mgmt Meeting | W13: =IF(COUNT(G13:T13)=0,"-",Dashboard!$I$6-MAX(G13:T13)) -> 48 | X13: Declined to proceed after review — cited valuation gap.
A14: B011 | B14: Ironwood Steel Works | C14: Strategic | D14: A | E14: Christopher MacAllister | F14: c.macallister@ironwood.com | G14: 46094 | H14: 46095 | I14: 46094 | J14: 46101 | K14: 46109 | L14: 46156 | M14: 7.8 | N14: 9 | O14: 46206 | U14: Declined | V14: =IF(T14<>"","9 - Closed",IF(S14<>"","8 - Definitive Agreement",IF(Q14<>"","7 - Diligence",IF(P14<>"","6 - LOI Signed",IF(O14<>"","5 - Mgmt Meeting",IF(L14<>"","4 - IOI Received",IF(K14<>"","3 - CIM Sent",IF(J14<>"","2 - NDA Signed",IF(I14<>"","1 - Teaser Sent","0 - Not Contacted"))))))))) -> 5 - Mgmt Meeting | W14: =IF(COUNT(G14:T14)=0,"-",Dashboard!$I$6-MAX(G14:T14)) -> 38 | X14: Declined to proceed after review — cited valuation gap.
A15: B012 | B15: Northbridge Investment Partners | C15: Private Equity | D15: B | E15: Rachel Delacroix | F15: r.delacroix@northbridge.com | G15: 46096 | H15: 46097 | I15: 46096 | J15: 46108 | K15: 46114 | L15: 46165 | M15: 12.7 | N15: 13.3 | O15: 46217 | U15: Declined | V15: =IF(T15<>"","9 - Closed",IF(S15<>"","8 - Definitive Agreement",IF(Q15<>"","7 - Diligence",IF(P15<>"","6 - LOI Signed",IF(O15<>"","5 - Mgmt Meeting",IF(L15<>"","4 - IOI Received",IF(K15<>"","3 - CIM Sent",IF(J15<>"","2 - NDA Signed",IF(I15<>"","1 - Teaser Sent","0 - Not Contacted"))))))))) -> 5 - Mgmt Meeting | W15: =IF(COUNT(G15:T15)=0,"-",Dashboard!$I$6-MAX(G15:T15)) -> 27 | X15: Declined to proceed after review — cited valuation gap.
A16: B013 | B16: Blackstone Falls Energy Services | C16: Strategic | D16: C | E16: Stephanie Whitcombe | F16: s.whitcombe@blackstone.com | G16: 46108 | H16: 46112 | I16: 46108 | J16: 46118 | K16: 46122 | L16: 46171 | M16: 12.2 | N16: 13.6 | O16: 46205 | U16: Declined | V16: =IF(T16<>"","9 - Closed",IF(S16<>"","8 - Definitive Agreement",IF(Q16<>"","7 - Diligence",IF(P16<>"","6 - LOI Signed",IF(O16<>"","5 - Mgmt Meeting",IF(L16<>"","4 - IOI Received",IF(K16<>"","3 - CIM Sent",IF(J16<>"","2 - NDA Signed",IF(I16<>"","1 - Teaser Sent","0 - Not Contacted"))))))))) -> 5 - Mgmt Meeting | W16: =IF(COUNT(G16:T16)=0,"-",Dashboard!$I$6-MAX(G16:T16)) -> 39 | X16: Declined to proceed after review — cited valuation gap.
A17: B014 | B17: Amberline Capital Partners | C17: Family Office | D17: B | E17: Megan Lindqvist | F17: m.lindqvist@amberline.com | G17: 46090 | H17: 46093 | I17: 46090 | J17: 46104 | K17: 46113 | L17: 46177 | M17: 8.2 | N17: 9.8 | U17: Declined | V17: =IF(T17<>"","9 - Closed",IF(S17<>"","8 - Definitive Agreement",IF(Q17<>"","7 - Diligence",IF(P17<>"","6 - LOI Signed",IF(O17<>"","5 - Mgmt Meeting",IF(L17<>"","4 - IOI Received",IF(K17<>"","3 - CIM Sent",IF(J17<>"","2 - NDA Signed",IF(I17<>"","1 - Teaser Sent","0 - Not Contacted"))))))))) -> 4 - IOI Received | W17: =IF(COUNT(G17:T17)=0,"-",Dashboard!$I$6-MAX(G17:T17)) -> 67 | X17: Declined to proceed after review — cited valuation gap.
A18: B015 | B18: Copperfield Manufacturing Corp. | C18: Strategic | D18: B | E18: Thomas Sorensen | F18: t.sorensen@copperfield.com | G18: 46095 | H18: 46099 | I18: 46095 | J18: 46108 | K18: 46113 | L18: 46157 | M18: 10.3 | N18: 11.5 | U18: On Hold | V18: =IF(T18<>"","9 - Closed",IF(S18<>"","8 - Definitive Agreement",IF(Q18<>"","7 - Diligence",IF(P18<>"","6 - LOI Signed",IF(O18<>"","5 - Mgmt Meeting",IF(L18<>"","4 - IOI Received",IF(K18<>"","3 - CIM Sent",IF(J18<>"","2 - NDA Signed",IF(I18<>"","1 - Teaser Sent","0 - Not Contacted"))))))))) -> 4 - IOI Received | W18: =IF(COUNT(G18:T18)=0,"-",Dashboard!$I$6-MAX(G18:T18)) -> 87 | X18: IOI received but not advanced to management meetings (lower or less certain bid). Held in reserve during exclusivity.
A19: B016 | B19: Chandler Partners LLC | C19: Private Equity | D19: C | E19: Andrew Bianchi | F19: a.bianchi@chandler.com | G19: 46095 | H19: 46099 | I19: 46095 | J19: 46105 | K19: 46107 | L19: 46190 | M19: 11.7 | N19: 13.3 | U19: On Hold | V19: =IF(T19<>"","9 - Closed",IF(S19<>"","8 - Definitive Agreement",IF(Q19<>"","7 - Diligence",IF(P19<>"","6 - LOI Signed",IF(O19<>"","5 - Mgmt Meeting",IF(L19<>"","4 - IOI Received",IF(K19<>"","3 - CIM Sent",IF(J19<>"","2 - NDA Signed",IF(I19<>"","1 - Teaser Sent","0 - Not Contacted"))))))))) -> 4 - IOI Received | W19: =IF(COUNT(G19:T19)=0,"-",Dashboard!$I$6-MAX(G19:T19)) -> 54 | X19: IOI received but not advanced to management meetings (lower or less certain bid). Held in reserve during exclusivity.
A20: B017 | B20: Larkspur Capital Group | C20: Private Equity | D20: C | E20: Danielle Fontaine | F20: d.fontaine@larkspur.com | G20: 46087 | H20: 46090 | I20: 46087 | J20: 46095 | K20: 46102 | L20: 46154 | M20: 10.9 | N20: 12.3 | U20: On Hold | V20: =IF(T20<>"","9 - Closed",IF(S20<>"","8 - Definitive Agreement",IF(Q20<>"","7 - Diligence",IF(P20<>"","6 - LOI Signed",IF(O20<>"","5 - Mgmt Meeting",IF(L20<>"","4 - IOI Received",IF(K20<>"","3 - CIM Sent",IF(J20<>"","2 - NDA Signed",IF(I20<>"","1 - Teaser Sent","0 - Not Contacted"))))))))) -> 4 - IOI Received | W20: =IF(COUNT(G20:T20)=0,"-",Dashboard!$I$6-MAX(G20:T20)) -> 90 | X20: IOI received but not advanced to management meetings (lower or less certain bid). Held in reserve during exclusivity.
A21: B018 | B21: Fieldstone Private Equity | C21: Private Equity | D21: A | E21: Megan Kowalski | F21: m.kowalski@fieldstone.com | G21: 46095 | H21: 46096 | I21: 46095 | J21: 46108 | K21: 46112 | L21: 46151 | M21: 11.9 | N21: 12.4 | U21: Declined | V21: =IF(T21<>"","9 - Closed",IF(S21<>"","8 - Definitive Agreement",IF(Q21<>"","7 - Diligence",IF(P21<>"","6 - LOI Signed",IF(O21<>"","5 - Mgmt Meeting",IF(L21<>"","4 - IOI Received",IF(K21<>"","3 - CIM Sent",IF(J21<>"","2 - NDA Signed",IF(I21<>"","1 - Teaser Sent","0 - Not Contacted"))))))))) -> 4 - IOI Received | W21: =IF(COUNT(G21:T21)=0,"-",Dashboard!$I$6-MAX(G21:T21)) -> 93 | X21: Declined to proceed after review — cited valuation gap.
A22: B019 | B22: Ironwood Process Equipment | C22: Strategic | D22: C | E22: Brian Ferris | F22: b.ferris@ironwood.com | G22: 46085 | H22: 46087 | I22: 46085 | J22: 46090 | K22: 46098 | L22: 46171 | M22: 8.2 | N22: 8.9 | U22: Declined | V22: =IF(T22<>"","9 - Closed",IF(S22<>"","8 - Definitive Agreement",IF(Q22<>"","7 - Diligence",IF(P22<>"","6 - LOI Signed",IF(O22<>"","5 - Mgmt Meeting",IF(L22<>"","4 - IOI Received",IF(K22<>"","3 - CIM Sent",IF(J22<>"","2 - NDA Signed",IF(I22<>"","1 - Teaser Sent","0 - Not Contacted"))))))))) -> 4 - IOI Received | W22: =IF(COUNT(G22:T22)=0,"-",Dashboard!$I$6-MAX(G22:T22)) -> 73 | X22: Declined to proceed after review — cited valuation gap.
A23: B020 | B23: Harrow Investment Partners | C23: Private Equity | D23: A | E23: Kevin Sorensen | F23: k.sorensen@harrow.com | G23: 46097 | H23: 46100 | I23: 46097 | J23: 46110 | K23: 46118 | L23: 46191 | M23: 7.7 | N23: 9.3 | U23: On Hold | V23: =IF(T23<>"","9 - Closed",IF(S23<>"","8 - Definitive Agreement",IF(Q23<>"","7 - Diligence",IF(P23<>"","6 - LOI Signed",IF(O23<>"","5 - Mgmt Meeting",IF(L23<>"","4 - IOI Received",IF(K23<>"","3 - CIM Sent",IF(J23<>"","2 - NDA Signed",IF(I23<>"","1 - Teaser Sent","0 - Not Contacted"))))))))) -> 4 - IOI Received | W23: =IF(COUNT(G23:T23)=0,"-",Dashboard!$I$6-MAX(G23:T23)) -> 53 | X23: IOI received but not advanced to management meetings (lower or less certain bid). Held in reserve during exclusivity.
A24: B021 | B24: Cobalt Private Equity | C24: Private Equity | D24: B | E24: Laura Novak | F24: l.novak@cobalt.com | G24: 46093 | H24: 46096 | I24: 46093 | J24: 46103 | K24: 46112 | L24: 46136 | M24: 7.4 | N24: 9.2 | U24: On Hold | V24: =IF(T24<>"","9 - Closed",IF(S24<>"","8 - Definitive Agreement",IF(Q24<>"","7 - Diligence",IF(P24<>"","6 - LOI Signed",IF(O24<>"","5 - Mgmt Meeting",IF(L24<>"","4 - IOI Received",IF(K24<>"","3 - CIM Sent",IF(J24<>"","2 - NDA Signed",IF(I24<>"","1 - Teaser Sent","0 - Not Contacted"))))))))) -> 4 - IOI Received | W24: =IF(COUNT(G24:T24)=0,"-",Dashboard!$I$6-MAX(G24:T24)) -> 108 | X24: IOI received but not advanced to management meetings (lower or less certain bid). Held in reserve during exclusivity.
A25: B022 | B25: Marlow Fund IV LP | C25: Family Office | D25: B | E25: Robert Beaudry | F25: r.beaudry@marlow.com | G25: 46107 | H25: 46111 | I25: 46107 | J25: 46121 | K25: 46125 | L25: 46170 | M25: 7 | N25: 8.2 | U25: Declined | V25: =IF(T25<>"","9 - Closed",IF(S25<>"","8 - Definitive Agreement",IF(Q25<>"","7 - Diligence",IF(P25<>"","6 - LOI Signed",IF(O25<>"","5 - Mgmt Meeting",IF(L25<>"","4 - IOI Received",IF(K25<>"","3 - CIM Sent",IF(J25<>"","2 - NDA Signed",IF(I25<>"","1 - Teaser Sent","0 - Not Contacted"))))))))) -> 4 - IOI Received | W25: =IF(COUNT(G25:T25)=0,"-",Dashboard!$I$6-MAX(G25:T25)) -> 74 | X25: Declined to proceed after review — cited valuation gap.
A26: B023 | B26: Highland Fabrication Group | C26: Strategic | D26: B | E26: Steven Reinholt | F26: s.reinholt@highland.com | G26: 46096 | H26: 46099 | I26: 46096 | J26: 46110 | K26: 46118 | L26: 46144 | M26: 10.9 | N26: 12.1 | U26: On Hold | V26: =IF(T26<>"","9 - Closed",IF(S26<>"","8 - Definitive Agreement",IF(Q26<>"","7 - Diligence",IF(P26<>"","6 - LOI Signed",IF(O26<>"","5 - Mgmt Meeting",IF(L26<>"","4 - IOI Received",IF(K26<>"","3 - CIM Sent",IF(J26<>"","2 - NDA Signed",IF(I26<>"","1 - Teaser Sent","0 - Not Contacted"))))))))) -> 4 - IOI Received | W26: =IF(COUNT(G26:T26)=0,"-",Dashboard!$I$6-MAX(G26:T26)) -> 100 | X26: IOI received but not advanced to management meetings (lower or less certain bid). Held in reserve during exclusivity.
A27: B024 | B27: Silverpeak Fund IV LP | C27: Private Equity | D27: A | E27: Thomas Vasquez | F27: t.vasquez@silverpeak.com | G27: 46083 | H27: 46086 | I27: 46083 | J27: 46097 | K27: 46100 | U27: Passed | V27: =IF(T27<>"","9 - Closed",IF(S27<>"","8 - Definitive Agreement",IF(Q27<>"","7 - Diligence",IF(P27<>"","6 - LOI Signed",IF(O27<>"","5 - Mgmt Meeting",IF(L27<>"","4 - IOI Received",IF(K27<>"","3 - CIM Sent",IF(J27<>"","2 - NDA Signed",IF(I27<>"","1 - Teaser Sent","0 - Not Contacted"))))))))) -> 3 - CIM Sent | W27: =IF(COUNT(G27:T27)=0,"-",Dashboard!$I$6-MAX(G27:T27)) -> 144 | X27: Received CIM; did not submit an IOI by the round-1 deadline (18-Jun-2026).
A28: B025 | B28: Wexford Partners LLC | C28: Private Equity | D28: A | E28: Danielle Kowalski | F28: d.kowalski@wexford.com | G28: 46094 | H28: 46098 | I28: 46094 | J28: 46104 | K28: 46114 | U28: Passed | V28: =IF(T28<>"","9 - Closed",IF(S28<>"","8 - Definitive Agreement",IF(Q28<>"","7 - Diligence",IF(P28<>"","6 - LOI Signed",IF(O28<>"","5 - Mgmt Meeting",IF(L28<>"","4 - IOI Received",IF(K28<>"","3 - CIM Sent",IF(J28<>"","2 - NDA Signed",IF(I28<>"","1 - Teaser Sent","0 - Not Contacted"))))))))) -> 3 - CIM Sent | W28: =IF(COUNT(G28:T28)=0,"-",Dashboard!$I$6-MAX(G28:T28)) -> 130 | X28: Reviewed CIM; passed before IOIs (not a strategic fit at this time).
A29: B026 | B29: Deerpath Growth Partners | C29: Private Equity | D29: A | E29: Emily Choudhury | F29: e.choudhury@deerpath.com | G29: 46103 | H29: 46104 | I29: 46103 | J29: 46106 | K29: 46116 | U29: Passed | V29: =IF(T29<>"","9 - Closed",IF(S29<>"","8 - Definitive Agreement",IF(Q29<>"","7 - Diligence",IF(P29<>"","6 - LOI Signed",IF(O29<>"","5 - Mgmt Meeting",IF(L29<>"","4 - IOI Received",IF(K29<>"","3 - CIM Sent",IF(J29<>"","2 - NDA Signed",IF(I29<>"","1 - Teaser Sent","0 - Not Contacted"))))))))) -> 3 - CIM Sent | W29: =IF(COUNT(G29:T29)=0,"-",Dashboard!$I$6-MAX(G29:T29)) -> 128 | X29: Reviewed CIM; passed before IOIs (not a strategic fit at this time).
A30: B027 | B30: Palisade Buyout Partners | C30: Private Equity | D30: A | E30: Sarah Delacroix | F30: s.delacroix@palisade.com | G30: 46090 | H30: 46092 | I30: 46090 | J30: 46102 | K30: 46110 | U30: Passed | V30: =IF(T30<>"","9 - Closed",IF(S30<>"","8 - Definitive Agreement",IF(Q30<>"","7 - Diligence",IF(P30<>"","6 - LOI Signed",IF(O30<>"","5 - Mgmt Meeting",IF(L30<>"","4 - IOI Received",IF(K30<>"","3 - CIM Sent",IF(J30<>"","2 - NDA Signed",IF(I30<>"","1 - Teaser Sent","0 - Not Contacted"))))))))) -> 3 - CIM Sent | W30: =IF(COUNT(G30:T30)=0,"-",Dashboard!$I$6-MAX(G30:T30)) -> 134 | X30: Reviewed CIM; passed before IOIs (not a strategic fit at this time).
A31: B028 | B31: Sable Point Partners LLC | C31: Private Equity | D31: A | E31: Robert Vasquez | F31: r.vasquez@sable.com | G31: 46087 | H31: 46091 | I31: 46087 | J31: 46102 | K31: 46108 | U31: Passed | V31: =IF(T31<>"","9 - Closed",IF(S31<>"","8 - Definitive Agreement",IF(Q31<>"","7 - Diligence",IF(P31<>"","6 - LOI Signed",IF(O31<>"","5 - Mgmt Meeting",IF(L31<>"","4 - IOI Received",IF(K31<>"","3 - CIM Sent",IF(J31<>"","2 - NDA Signed",IF(I31<>"","1 - Teaser Sent","0 - Not Contacted"))))))))) -> 3 - CIM Sent | W31: =IF(COUNT(G31:T31)=0,"-",Dashboard!$I$6-MAX(G31:T31)) -> 136 | X31: Received CIM; did not submit an IOI by the round-1 deadline (18-Jun-2026).
A32: B029 | B32: Crestview Pressure Systems | C32: Strategic | D32: B | E32: Emily Nakamura | F32: e.nakamura@crestview.com | G32: 46086 | H32: 46087 | I32: 46086 | J32: 46096 | K32: 46106 | U32: Passed | V32: =IF(T32<>"","9 - Closed",IF(S32<>"","8 - Definitive Agreement",IF(Q32<>"","7 - Diligence",IF(P32<>"","6 - LOI Signed",IF(O32<>"","5 - Mgmt Meeting",IF(L32<>"","4 - IOI Received",IF(K32<>"","3 - CIM Sent",IF(J32<>"","2 - NDA Signed",IF(I32<>"","1 - Teaser Sent","0 - Not Contacted"))))))))) -> 3 - CIM Sent | W32: =IF(COUNT(G32:T32)=0,"-",Dashboard!$I$6-MAX(G32:T32)) -> 138 | X32: Received CIM; did not submit an IOI by the round-1 deadline (18-Jun-2026).
A33: B030 | B33: Cascade Process Equipment | C33: Strategic | D33: B | E33: Brian Sinclair | F33: b.sinclair@cascade.com | G33: 46091 | H33: 46094 | I33: 46091 | J33: 46096 | K33: 46105 | U33: Passed | V33: =IF(T33<>"","9 - Closed",IF(S33<>"","8 - Definitive Agreement",IF(Q33<>"","7 - Diligence",IF(P33<>"","6 - LOI Signed",IF(O33<>"","5 - Mgmt Meeting",IF(L33<>"","4 - IOI Received",IF(K33<>"","3 - CIM Sent",IF(J33<>"","2 - NDA Signed",IF(I33<>"","1 - Teaser Sent","0 - Not Contacted"))))))))) -> 3 - CIM Sent | W33: =IF(COUNT(G33:T33)=0,"-",Dashboard!$I$6-MAX(G33:T33)) -> 139 | X33: Reviewed CIM; passed before IOIs (not a strategic fit at this time).
A34: B031 | B34: Whitecliff Piping Solutions | C34: Strategic | D34: A | E34: Ryan Callahan | F34: r.callahan@whitecliff.com | G34: 46102 | H34: 46106 | I34: 46102 | J34: 46111 | K34: 46115 | U34: Passed | V34: =IF(T34<>"","9 - Closed",IF(S34<>"","8 - Definitive Agreement",IF(Q34<>"","7 - Diligence",IF(P34<>"","6 - LOI Signed",IF(O34<>"","5 - Mgmt Meeting",IF(L34<>"","4 - IOI Received",IF(K34<>"","3 - CIM Sent",IF(J34<>"","2 - NDA Signed",IF(I34<>"","1 - Teaser Sent","0 - Not Contacted"))))))))) -> 3 - CIM Sent | W34: =IF(COUNT(G34:T34)=0,"-",Dashboard!$I$6-MAX(G34:T34)) -> 129 | X34: Received CIM; did not submit an IOI by the round-1 deadline (18-Jun-2026).
A35: B032 | B35: Chandler Industrial Capital | C35: Private Equity | D35: A | E35: Danielle Renard | F35: d.renard@chandler.com | G35: 46088 | H35: 46091 | I35: 46088 | J35: 46101 | K35: 46110 | U35: Passed | V35: =IF(T35<>"","9 - Closed",IF(S35<>"","8 - Definitive Agreement",IF(Q35<>"","7 - Diligence",IF(P35<>"","6 - LOI Signed",IF(O35<>"","5 - Mgmt Meeting",IF(L35<>"","4 - IOI Received",IF(K35<>"","3 - CIM Sent",IF(J35<>"","2 - NDA Signed",IF(I35<>"","1 - Teaser Sent","0 - Not Contacted"))))))))) -> 3 - CIM Sent | W35: =IF(COUNT(G35:T35)=0,"-",Dashboard!$I$6-MAX(G35:T35)) -> 134 | X35: Reviewed CIM; passed before IOIs (not a strategic fit at this time).
A36: B033 | B36: Millbrook Energy Services | C36: Strategic | D36: B | E36: Rachel Talbot | F36: r.talbot@millbrook.com | G36: 46092 | H36: 46095 | I36: 46092 | J36: 46100 | K36: 46109 | U36: Passed | V36: =IF(T36<>"","9 - Closed",IF(S36<>"","8 - Definitive Agreement",IF(Q36<>"","7 - Diligence",IF(P36<>"","6 - LOI Signed",IF(O36<>"","5 - Mgmt Meeting",IF(L36<>"","4 - IOI Received",IF(K36<>"","3 - CIM Sent",IF(J36<>"","2 - NDA Signed",IF(I36<>"","1 - Teaser Sent","0 - Not Contacted"))))))))) -> 3 - CIM Sent | W36: =IF(COUNT(G36:T36)=0,"-",Dashboard!$I$6-MAX(G36:T36)) -> 135 | X36: Reviewed CIM; passed before IOIs (not a strategic fit at this time).
A37: B034 | B37: Wexford Capital Partners | C37: Family Office | D37: C | E37: Brian Bianchi | F37: b.bianchi@wexford.com | G37: 46095 | H37: 46097 | I37: 46095 | J37: 46109 | K37: 46113 | U37: Passed | V37: =IF(T37<>"","9 - Closed",IF(S37<>"","8 - Definitive Agreement",IF(Q37<>"","7 - Diligence",IF(P37<>"","6 - LOI Signed",IF(O37<>"","5 - Mgmt Meeting",IF(L37<>"","4 - IOI Received",IF(K37<>"","3 - CIM Sent",IF(J37<>"","2 - NDA Signed",IF(I37<>"","1 - Teaser Sent","0 - Not Contacted"))))))))) -> 3 - CIM Sent | W37: =IF(COUNT(G37:T37)=0,"-",Dashboard!$I$6-MAX(G37:T37)) -> 131 | X37: Reviewed CIM; passed before IOIs (not a strategic fit at this time).
A38: B035 | B38: Whitecliff Energy Infrastructure | C38: Strategic | D38: A | E38: Christopher Renard | F38: c.renard@whitecliff.com | G38: 46101 | H38: 46104 | I38: 46101 | J38: 46109 | K38: 46114 | U38: Passed | V38: =IF(T38<>"","9 - Closed",IF(S38<>"","8 - Definitive Agreement",IF(Q38<>"","7 - Diligence",IF(P38<>"","6 - LOI Signed",IF(O38<>"","5 - Mgmt Meeting",IF(L38<>"","4 - IOI Received",IF(K38<>"","3 - CIM Sent",IF(J38<>"","2 - NDA Signed",IF(I38<>"","1 - Teaser Sent","0 - Not Contacted"))))))))) -> 3 - CIM Sent | W38: =IF(COUNT(G38:T38)=0,"-",Dashboard!$I$6-MAX(G38:T38)) -> 130 | X38: Reviewed CIM; passed before IOIs (not a strategic fit at this time).
... A73: B070 | B73: Thornfield Industrial Capital | C73: Private Equity | D73: A | E73: David Duquette | F73: d.duquette@thornfield.com | G73: 46084 | H73: 46086 | I73: 46084 | J73: 46094 | K73: 46096 | U73: Passed | V73: =IF(T73<>"","9 - Closed",IF(S73<>"","8 - Definitive Agreement",IF(Q73<>"","7 - Diligence",IF(P73<>"","6 - LOI Signed",IF(O73<>"","5 - Mgmt Meeting",IF(L73<>"","4 - IOI Received",IF(K73<>"","3 - CIM Sent",IF(J73<>"","2 - NDA Signed",IF(I73<>"","1 - Teaser Sent","0 - Not Contacted"))))))))) -> 3 - CIM Sent | W73: =IF(COUNT(G73:T73)=0,"-",Dashboard!$I$6-MAX(G73:T73)) -> 148 | X73: Received CIM; did not submit an IOI by the round-1 deadline (18-Jun-2026).
A74: B071 | B74: Wexford Industrial Capital | C74: Family Office | D74: C | E74: Stephanie Marchand | F74: s.marchand@wexford.com | G74: 46087 | H74: 46088 | I74: 46087 | U74: Passed | V74: =IF(T74<>"","9 - Closed",IF(S74<>"","8 - Definitive Agreement",IF(Q74<>"","7 - Diligence",IF(P74<>"","6 - LOI Signed",IF(O74<>"","5 - Mgmt Meeting",IF(L74<>"","4 - IOI Received",IF(K74<>"","3 - CIM Sent",IF(J74<>"","2 - NDA Signed",IF(I74<>"","1 - Teaser Sent","0 - Not Contacted"))))))))) -> 1 - Teaser Sent | W74: =IF(COUNT(G74:T74)=0,"-",Dashboard!$I$6-MAX(G74:T74)) -> 156 | X74: Received blind teaser and NDA; NDA not executed (passed on size or sector fit).
...

Sheet Buyer Universe
A1: BUYER UNIVERSE / TARGET LIST — PROJECT IRONBEND
A2: Real, named strategic and financial buyers screened for Northline Precision Pipe Bending & Fabrication Ltd. (ASME 'U'-Stamp / National Board certified pipe bending & pressure vessel fabricator, Edmonton, AB; ~$9.4mm 2025E revenue). Compiled from public company filings, press releases, and firm websites — see Source column. Not an exhaustive list.
A3: # | B3: Buyer Name | C3: Type | D3: HQ / Region | E3: Public / Private | F3: Rationale / Strategic Fit | G3: Est. Check Size / Capacity | H3: Prior Relevant Acquisitions | I3: Source
A4: STRATEGIC BUYERS
A5: 1 | B5: CESSCO Fabrication & Engineering Ltd. | C5: Strategic | D5: Nisku, AB | E5: Private | F5: Direct regional competitor. ~75-year-old Alberta pressure vessel fabricator with multiple ASME and ABSA certifications, serving the same oil & gas / petrochemical / mining customer base in Western Canada's high-load corridor. Acquisition would consolidate certified fabrication capacity and backlog in-region. | G5: Not publicly disclosed (privately held; no PE sponsor identified). | H5: None identified in public sources. | I5: cessco.ca
A6: 2 | B6: Alberta Custom Pipe Bending & Mfg. (2010) Ltd. | C6: Strategic | D6: Edmonton, AB | E6: Private | F6: Near-identical certification and service profile to the Company — ASME and National Board certified fabricator in the same Edmonton industrial corridor. A direct, same-city competitor; combination would remove a head-to-head bidder on certified pipe bending / pressure vessel work and add capacity. | G6: Not publicly disclosed (privately held). | H6: None identified in public sources. | I6: acpbm.com
A7: 3 | B7: Bri-Steel Manufacturing (Integris International Inc.) | C7: Strategic | D7: Edmonton, AB | E7: Private | F7: Edmonton-based large-diameter seamless steel pipe manufacturer (NPS 12-36") serving oil & gas, pipeline and infrastructure customers; API/ASME/CSA certified. Adding Northline's bending and pressure vessel capability would let Bri-Steel offer fabricated/bent pipe products alongside its mill output — a logical vertical extension for an already-acquisitive, expansion-minded manufacturer. | G7: ~US$23.4mm 2025 revenue (Bri-Steel); scale suggests capacity for a bolt-on of this size, but not publicly confirmed. | H7: Acquired the former GEFCO facility (Enid, OK) to build a second Thermal Pipe Expansion mill (asset purchase, not a company acquisition). | I7: ZoomInfo; manufacturinginfocus.com; bri-steel.com
A8: 4 | B8: JNE Welding | C8: Strategic | D8: Saskatoon, SK | E8: Private | F8: One of Saskatchewan's largest full-service pressure vessel fabricators (77,000 sq ft shop, vessels up to 250 tons), serving oil sands, mining and potash customers. Geographic and end-market adjacency to Northline with limited certified-fabrication overlap — a bolt-on would extend JNE's footprint into Alberta's oil & gas base. | G8: Not publicly disclosed (privately held). | H8: None identified in public sources. | I8: jnewelding.com
A9: 5 | B9: Moss Fabrication Ltd. | C9: Strategic | D9: Calgary, AB | E9: Private | F9: Calgary-based fabricator of pressure vessels, separators and skid packages for Western Canadian gas and oilfields since 1983, CSA/API/ASME compliant. Smaller regional player for whom acquiring Northline's ASME 'U'-Stamp and National Board dual certification would be a fast route to code-stamped pressure vessel work it cannot currently bid without third-party certification. | G9: Not publicly disclosed (privately held). | H9: None identified in public sources. | I9: mossfabrication.ca
A10: 6 | B10: Matrix Service Company | C10: Strategic | D10: Tulsa, OK (NASDAQ: MTRX) | E10: Public | F10: Public EPC and fabrication company for aboveground storage tanks, terminals and ASME pressure vessels, with existing U.S. and Canadian operations. A serial acquirer of smaller fabrication and piping businesses historically; Northline's certified capacity and Tier-1 O&G relationships would extend Matrix's Storage and Terminal Solutions / Process and Industrial Facilities segments into Western Canada. | G10: Public company; funds bolt-ons from cash + credit facility. Comparable historical deal was <US$10mm (2014 upstream contractor acquisition). | H10: San Luis Piping Construction & West Coast Industrial Coatings (~US$10.2mm, 1991); Health Engineering, Sarnia ON (1993); PDM Engineering; Houston Interests/River Consulting group (2016); Baillie Tank Equipment (2016); an upstream contractor for <US$10mm (2014). | I10: matrixservicecompany.com; PitchBook; investors.matrixservicecompany.com
A11: 7 | B11: Total Energy Services Inc. | C11: Strategic | D11: Calgary, AB (TSX: TOT) | E11: Public | F11: Public, Calgary-based diversified energy services company whose Compression and Process Services segment (Bidell Gas Compression / process equipment fabrication) is the majority revenue driver. Explicit 'disciplined acquisition strategy' for fabrication and process equipment businesses — Northline's ASME/NB certification would add pressure vessel capability alongside Total's existing compression fabrication. | G11: Public company (TSX: TOT); stock ~C$19/share as of mid-2026. Deal sizing not disclosed for fabrication bolt-ons specifically. | H11: Multiple acquisitions incl. Savanna Energy Services merger (2017, drilling); Korea National Oil asset purchase (2025). | I11: totalenergy.ca; PitchBook; SEC filings
A12: 8 | B12: DXP Enterprises, Inc. | C12: Strategic | D12: Houston, TX (NASDAQ: DXPE) | E12: Public | F12: Public industrial MROP distributor operating an explicit, disclosed roll-up model (17+ acquisitions since 2004) with a demonstrated pattern of small Western Canadian bolt-ons at revenue scale directly comparable to Northline. Certified fabrication capability would be a natural adjacent-service addition to DXP's existing Alberta operations. | G12: Directly comparable disclosed deals: Mequipco Ltd. (Calgary, ~CAD$9.9mm revenue, 2026) and Industrial Paramedic Services (Calgary/Nisku, ~US$21mm revenue / ~US$4mm EBITDA, 2012) — both funded with cash + stock. | H12: Industrial Paramedic Services, Calgary/Nisku (2012); Mequipco Ltd., Calgary (2026); 15+ other bolt-ons since 2004 (Delta Process Equipment, Precision Industries, Rocky Mtn. Supply, PFI, others). | I12: SEC 8-K filings; investing.com; ir.dxpe.com
A13: 9 | B13: Enerflex Ltd. | C13: Strategic | D13: Calgary, AB (TSX/NYSE: EFXT) | E13: Public | F13: Public Calgary-based manufacturer of natural gas compression and process equipment with an active M&A program. Adjacent process-equipment fabricator; Northline's pressure vessel and pipe bending capability would complement Enerflex's compression package fabrication and broaden its certified product scope. | G13: Public company (TSX/NYSE: EFXT); deal sizing not disclosed for fabrication-scale bolt-ons. | H13: Absolute Compression Enterprise (2023) and 5 other acquisitions on record. | I13: PitchBook; GlobalData
A14: FINANCIAL BUYERS
A15: 10 | B15: Clairvest Group Inc. | C15: Financial | D15: Toronto, ON (TSX: CVG) | E15: Public (PE firm) | F15: Publicly listed Canadian PE firm with an explicitly stated mandate to invest in 'small and mid-sized... oil and gas field services' businesses, among other sectors — one of the few listed sponsors with named oilfield-services intent. Long Toronto/Calgary investor relationships and a consolidation/add-on playbook fit a certification-moat platform like Northline. | G15: ~C$4.6bn capital under management; recent disclosed deals range ~US$30-165mm (e.g., MGM Northfield Park, US$165mm total / US$39mm CVG portion) — likely larger than this target, but smaller platform + add-on strategy possible. | H15: No pipe/pressure-vessel-fabrication acquisition identified specifically; broad oilfield services mandate confirmed on firm website. | I15: clairvest.com; investing.com; ZoomInfo
A16: 11 | B16: Kinderhook Industries, LLC | C16: Financial | D16: New York, NY | E16: Private (PE firm) | F16: Lower-middle-market PE firm with 'Environmental & Industrial Services' as one of three named core sectors and 500+ investments/add-ons since 2003. Platform-and-bolt-on model suits a certification-protected niche fabricator; scale is a modest stretch above their typical minimum. | G16: Stated criteria: US$10-50mm equity checks; EV range US$25-150mm — above Northline's $9-13mm indicative range, but a new lower middle-market vehicle (Kinderhook Strategic Opportunities Fund I, $1.1bn, closed 2026) may flex smaller. | H16: No pipe/pressure-vessel-fabrication acquisition identified specifically. | I16: kinderhook.com; Eagle Rock CFO; PR Newswire (KSOF close, Apr 2026)
A17: 12 | B17: CORE Industrial Partners | C17: Financial | D17: Chicago, IL | E17: Private (PE firm) | F17: PE firm investing exclusively in lower-middle-market manufacturing, industrial technology and industrial services businesses — sector focus matches a certified fabricator well; explicitly LMM-sized mandate is a closer fit to Northline's scale than most funds on this list. | G17: Firm-level: >US$1.58bn capital commitments; per-deal check size not publicly disclosed. | H17: No pipe/pressure-vessel-fabrication acquisition identified specifically (recent exit: PrecisionX Group, precision machining). | I17: coreipfund.com
A18: 13 | B18: Wynnchurch Capital, L.P. | C18: Financial | D18: Rosemont, IL (Canadian affiliate) | E18: Private (PE firm) | F18: Middle-market industrial PE firm with a standing Canadian affiliate and a specific track record of metals and industrial-services roll-ups (aluminum extrusions, MRO field services, critical infrastructure equipment) — the closest sector-and-geography match among the larger funds screened. | G18: ~US$9.2bn regulatory AUM; recent disclosed deal sizes range widely (e.g., FloWorks sale at ~US$1.6bn EV) — individual platforms are typically larger than this target; most likely fit would be as an add-on to an existing Wynnchurch industrial-services or metals platform. | H18: Astro Shapes (aluminum extrusions); Industrial Service Solutions / ISS (MRO field services); Owen (critical infrastructure equipment); Charter Industries (2025). | I18: wynnchurch.com (news releases)
A19: 14 | B19: Industrial Opportunity Partners (IOP) | C19: Financial | D19: Evanston, IL | E19: Private (PE firm) | F19: PE firm focused exclusively on middle-market manufacturing and value-added distribution, with prior acquisitions in two Canadian provinces — demonstrated willingness and infrastructure to close Canadian deals, though its typical target revenue ($50-500mm) is larger than Northline's. | G19: Stated equity check: US$15-100mm per transaction — above Northline's scale; would more likely appear as an add-on sponsor via an existing platform than a standalone bidder. | H19: 30+ platform acquisitions since 2005 (e.g., Viaflex/Raven Engineered Films, N.B. Handy); none identified in pipe/pressure-vessel fabrication specifically. | I19: iopfund.com; Mergr
A20: 15 | B20: American Industrial Partners | C20: Financial | D20: New York, NY | E20: Private (PE firm) | F20: Deeply industrial-focused PE firm (Energy Services and Equipment named as a sector of interest) with 125+ platform and add-on acquisitions — sector fit is strong, but included primarily for completeness: their stated minimum platform size is well above Northline's revenue. | G20: ~US$16-17.8bn AUM; platform acquisitions typically require >US$500mm revenue — a clear size mismatch for a US$9.4mm-revenue target; realistic only as a bolt-on to an existing AIP portfolio company, if any overlaps. | H20: 125+ acquisitions across industrial sectors; GD Energy Products (industrial pumps) is the closest sector analog identified. | I20: americanindustrial.com; Mergr; CT Acquisitions directory
A21: 16 | B21: Birch Hill Equity Partners | C21: Financial | D21: Toronto, ON | E21: Private (PE firm) | F21: Established Canadian mid-market generalist sponsor (Energy Services and Equipment named as a sector of interest) with a long history of Canadian industrial deals — included for completeness, but its stated deal-size floor is well above this target. | G21: Targets control/significant-minority deals valued C$75mm-$3bn (per Mergr) — roughly 5-10x larger than Northline's indicative $9-13mm EV; a size mismatch unless deployed as an add-on to an existing platform. | H21: 90 M&A transactions on record; none identified in pipe/pressure-vessel fabrication specifically. | I21: birchhillequity.com; Mergr; PitchBook
A23: LEGEND
A24: Green = sector fit AND check size plausibly matches Northline's $9-13mm indicative EV. Yellow = sector fit confirmed, but firm's typical/stated deal size is larger than this target — a realistic bolt-on/add-on candidate rather than a standalone lead bidder.
A26: Research notes: all organizations above are real, named companies verified via public filings, company websites, and news/PE-database sources as of August 2026 (see Source column for each). Fields marked 'not publicly disclosed' reflect genuine gaps in available public data for privately held companies — left blank/noted rather than estimated. This is a screened starting universe (16 names) for further analyst diligence, not an exhaustive or final buyer list; actual check size and appetite would be confirmed through direct buyer-side conversations.

Sheet Diligence Checklist
A1: DILIGENCE CHECKLIST — PROJECT IRONBEND (LEAD BUYER: B001, EXCLUSIVITY)
A2: Stage 7 of the deal process. Update Status and % Complete as items close out — the dashboard summary reads from this tab.
A3: # | B3: Category | C3: Diligence Item | D3: Owner | E3: Status | F3: Target Date | G3: Notes
A4: 1 | B4: Financial | C4: Audited financial statements — FY2023-2025 | D4: Advisor / CFO | E4: Complete | F4: 46235 | G4: Received; reviewed by buyer's QoE team
A5: 2 | B5: Financial | C5: Quality of Earnings (QoE) report | D5: Buyer's Accountant | E5: In Progress | F5: 46254 | G5: Fieldwork underway, on-site this week
A6: 3 | B6: Financial | C6: Working capital analysis & target | D6: Advisor / CFO | E6: In Progress | F6: 46252 | G6: Draft peg schedule circulated
A7: 4 | B7: Financial | C7: Backlog and order book schedule | D7: Company | E7: Complete | F7: 46235 | G7: NPS 6-42 backlog by customer provided
A8: 5 | B8: Financial | C8: Customer concentration analysis | D8: Advisor | E8: Complete | F8: 46233 | G8: Top 5 customers = ~59% of revenue; largest ~18% (matches CIM)
A9: 6 | B9: Legal | C9: Corporate structure & cap table review | D9: Buyer's Counsel | E9: Complete | F9: 46235 | G9: No issues identified
A10: 7 | B10: Legal | C10: Material contracts review (MSAs) | D10: Buyer's Counsel | E10: In Progress | F10: 46256 | G10: Tier-1 operator MSAs under review
A11: 8 | B11: Legal | C11: Litigation & claims history | D11: Buyer's Counsel | E11: Complete | F11: 46239 | G11: No pending litigation
A12: 9 | B12: Legal | C12: IP / trade secrets (bending procedures) | D12: Buyer's Counsel | E12: Not Started | F12: 46259
A13: 10 | B13: Regulatory | C13: ASME 'U'-Stamp certification status | D13: Buyer / QA Lead | E13: Complete | F13: 46237 | G13: Current, next audit Q1 2027
A14: 11 | B14: Regulatory | C14: National Board registration status | D14: Buyer / QA Lead | E14: Complete | F14: 46237 | G14: Current, in good standing
A15: 12 | B15: Regulatory | C15: ABSA certification & inspection history | D15: Buyer / QA Lead | E15: In Progress | F15: 46254 | G15: Requesting 5-yr inspection file
A16: 13 | B16: Regulatory | C16: CRN registration schedule (by province) | D16: Buyer / QA Lead | E16: Not Started | F16: 46259
A17: 14 | B17: Commercial | C17: Customer reference calls (top 5) | D17: Buyer / Advisor | E17: In Progress | F17: 46262 | G17: 3 of 5 calls completed
A18: 15 | B18: Commercial | C18: Competitive positioning review | D18: Buyer | E18: Not Started | F18: 46266
A19: 16 | B19: Commercial | C19: Pricing & contract renewal terms | D19: Advisor | E19: In Progress | F19: 46254 | G19: Reviewing MSA renewal cadence
A20: 17 | B20: Operations | C20: Facility & equipment condition assessment | D20: Buyer's Engineer | E20: In Progress | F20: 46259 | G20: Site visit scheduled Aug 12
A21: 18 | B21: Operations | C21: Capacity utilization & throughput analysis | D21: Company | E21: Not Started | F21: 46266
A22: 19 | B22: Operations | C22: Safety & environmental compliance (EHS) | D22: Buyer's Consultant | E22: Not Started | F22: 46266
A23: 20 | B23: Operations | C23: Supplier concentration & raw material sourcing | D23: Company | E23: Complete | F23: 46239 | G23: Steel supply diversified, 4 mills
A24: 21 | B24: HR | C24: Key employee / management retention review | D24: Buyer | E24: In Progress | F24: 46256 | G24: Retention packages under discussion
A25: 22 | B25: HR | C25: Union / labor agreement review | D25: Buyer's Counsel | E25: Complete | F25: 46239 | G25: Non-union shop confirmed
A26: 23 | B26: HR | C26: Compensation & benefits benchmarking | D26: Buyer | E26: Not Started | F26: 46270
A27: 24 | B27: IT | C27: IT systems & cybersecurity assessment | D27: Buyer's IT Consultant | E27: Not Started | F27: 46270
A28: 25 | B28: Tax | C28: Tax structuring & historical filings review | D28: Buyer's Tax Advisor | E28: In Progress | F28: 46262 | G28: Federal & Alberta filings requested
A29: 26 | B29: Insurance | C29: Insurance policy review (property, liability, WCB) | D29: Buyer | E29: Not Started | F29: 46270
A31: % COMPLETE (AUTO)
A32: Diligence items closed out: | D32: =COUNTIF(E4:E29,"Complete")&" of "&COUNTA(E4:E29)&" items" -> 9 of 26 items | F32: =COUNTIF(E4:E29,"Complete")/COUNTA(E4:E29) -> 0.34615385

Sheet Instructions
A1: HOW THIS WORKBOOK WORKS
A3: 1. STRUCTURE
B4: • Dashboard — the one-pager. Shows the 9-stage deal funnel (Teaser → NDA → CIM → IOI → Management Meeting → LOI → Diligence → Definitive Agreement → Close), pipeline status mix, IOI valuation range, and the overall deal milestone timeline for Project Ironbend. Everything except the report date and the milestone table is a live formula.
B5: • Buyer Tracker — the working tracker. 138 rows pre-loaded: 122 buyers contacted with the blind teaser, plus 16 real buyers freshly sourced from the Buyer Universe tab (Status = Not Contacted, no dates yet). Add new buyers by inserting rows within the table range (row 4 through the last data row) so formulas and formatting copy down automatically.
B6: • Diligence Checklist — detailed checklist for the buyer in exclusivity (26 items across Financial, Legal, Regulatory, Commercial, Operations, HR, IT, Tax and Insurance workstreams), with an auto-calculated % complete.
B7: • Buyer Universe — sourcing reference. 16 real, named strategic and financial buyers researched for this deal (public filings, company sites, press releases), each with rationale/fit, estimated check size, prior relevant acquisitions and a source citation. These are the same 16 buyers appended to the bottom of the Buyer Tracker as "Not Contacted" — update them there once outreach begins.
A9: 2. WHAT TO EDIT
B10: Buyer Tracker — edit freely (shown in blue font): columns G-T (process dates), M-N (IOI value range), U (Status dropdown), C (Type dropdown), D (Priority dropdown), X (Notes). Enter a date the moment a milestone happens (e.g. the day an NDA is countersigned goes in column J).
B11: Buyer Tracker — do NOT edit columns V (Current Stage) and W (Days Since Update). These are formulas that read the date columns automatically.
B12: Diligence Checklist — edit Status (dropdown) and Notes as items close out; the % Complete line at the bottom recalculates itself.
B13: Dashboard — only the report date (I6) and the Target Date / Actual Date / Status cells in the 'Overall Deal Milestone Timeline' table are manual. Everything else (KPI strip, funnel, pipeline status, IOI range, current-stage line) is a formula — do not type over it.
A15: 3. HOW THE AUTO-UPDATING WORKS
B16: Current Stage (Buyer Tracker, col V): checks each buyer's date columns from Close backward to Teaser Sent and returns the furthest milestone reached — no manual selection needed.
B17: Days Since Update (col W): the Dashboard report date minus the most recent date entered for that buyer — flags stale rows in bold amber automatically if a buyer marked Active hasn't moved in 21+ days. Set the report date to today's date when you update the tracker.
B18: Dashboard funnel counts: each stage box uses COUNT() on the corresponding Buyer Tracker date column (e.g. NDA count = COUNT of non-blank cells in column J), so it always reflects the current state of the tracker.
B19: Dashboard KPIs, status mix, and IOI range: COUNT/COUNTIF/AVERAGE/MIN/MAX formulas referencing the Buyer Tracker range — update instantly as you edit tracker rows.
A21: 4. SCALING BEYOND 138 BUYERS
B22: Select the last data row in Buyer Tracker, right-click, Insert Copied Cells (or select the full row and Insert), then fill down columns V and W and the border/zebra formatting from the row above. All Dashboard formulas reference the fixed range B4:X141 by default — if you add rows beyond row 141, extend the ranges in the Dashboard formulas (Find & Replace 141 with your new last row) and re-apply the Buyer Tracker data validations and conditional formatting to the new rows.
A24: 5. FORMATTING KEY
B25: Blue text = manual input (safe to edit). Dark grey/black text = formula output (leave alone). Navy header bands mark table headers. Status is shown by text styling rather than colour fills: bold navy = active / in progress, grey = not started or no longer in play, italic grey = no response / on hold. Amber bold in 'Days Since Update' flags an Active buyer with no movement for 21+ days.
